Workbook

Sheet Parametri
A1: L | B1: err_L | C1: sigma_L
A4: D | B4: err_D | C4: sigma_D
A7: y_0 | B7: err_y0 | C7: sigma_y0 | D7: sigma_y
B8: 0.2 | C8: =B8/SQRT(3) -> 0.11547005 | D8: =B8/SQRT(3) -> 0.11547005
A10: x_0 | B10: err_x0 | C10: sigma_x0 | D10: sigma_x
B11: 0.2 | C11: =B11/SQRT(3) -> 0.11547005 | D11: =B11/SQRT(3) -> 0.11547005

Sheet Dati (2)
A1: x | B1: y_min | C1: y_max | D1: y_max2 | E1: y | F1: sigma_y | G1: p | H1: q | I1: sigma_p | J1: sigma_q
A2: 270 | D2: =B2+2*E2 -> 3950 | E2: 1975 | F2: =IF(C2=0, Parametri!$D$8, ABS(B2-C2)/(2*SQRT(3))) -> 0.11547005 | G2: =(A2-335)+135.8+(Parametri!$A$5/2) -> 70.8 | H2: =(E2-192)-('Dati (2)'!A2-Parametri!$A$11)+Parametri!$A$2 -> 1513 | I2: =F2 -> 0.11547005 | J2: =Parametri!$D$8 -> 0.11547005
A3: =A2+1 -> 271 | D3: =B3+2*E3 -> 3950 | E3: 1975 | F3: =IF(C3=0, Parametri!$D$8, ABS(B3-C3)/(2*SQRT(3))) -> 0.11547005 | G3: =(A3-335)+135.8+(Parametri!$A$5/2) -> 71.8 | H3: =(E3-192)-('Dati (2)'!A3-Parametri!$A$11)+Parametri!$A$2 -> 1512 | I3: =F3 -> 0.11547005 | J3: =Parametri!$D$8 -> 0.11547005
A4: =A3+1 -> 272 | D4: =B4+2*E4 -> 3824 | E4: 1912 | F4: =IF(C4=0, Parametri!$D$8, ABS(B4-C4)/(2*SQRT(3))) -> 0.11547005 | G4: =(A4-335)+135.8+(Parametri!$A$5/2) -> 72.8 | H4: =(E4-192)-('Dati (2)'!A4-Parametri!$A$11)+Parametri!$A$2 -> 1448 | I4: =F4 -> 0.11547005 | J4: =Parametri!$D$8 -> 0.11547005
A5: =A4+1 -> 273 | D5: =B5+2*E5 -> 3786 | E5: 1893 | F5: =IF(C5=0, Parametri!$D$8, ABS(B5-C5)/(2*SQRT(3))) -> 0.11547005 | G5: =(A5-335)+135.8+(Parametri!$A$5/2) -> 73.8 | H5: =(E5-192)-('Dati (2)'!A5-Parametri!$A$11)+Parametri!$A$2 -> 1428 | I5: =F5 -> 0.11547005 | J5: =Parametri!$D$8 -> 0.11547005
A6: =A5+1 -> 274 | D6: =B6+2*E6 -> 3634 | E6: 1817 | F6: =IF(C6=0, Parametri!$D$8, ABS(B6-C6)/(2*SQRT(3))) -> 0.11547005 | G6: =(A6-335)+135.8+(Parametri!$A$5/2) -> 74.8 | H6: =(E6-192)-('Dati (2)'!A6-Parametri!$A$11)+Parametri!$A$2 -> 1351 | I6: =F6 -> 0.11547005 | J6: =Parametri!$D$8 -> 0.11547005
A7: =A6+1 -> 275 | D7: =B7+2*E7 -> 3566 | E7: 1783 | F7: =IF(C7=0, Parametri!$D$8, ABS(B7-C7)/(2*SQRT(3))) -> 0.11547005 | G7: =(A7-335)+135.8+(Parametri!$A$5/2) -> 75.8 | H7: =(E7-192)-('Dati (2)'!A7-Parametri!$A$11)+Parametri!$A$2 -> 1316 | I7: =F7 -> 0.11547005 | J7: =Parametri!$D$8 -> 0.11547005
A8: =A7+1 -> 276 | D8: =B8+2*E8 -> 3447 | E8: 1723.5 | F8: =IF(C8=0, Parametri!$D$8, ABS(B8-C8)/(2*SQRT(3))) -> 0.11547005 | G8: =(A8-335)+135.8+(Parametri!$A$5/2) -> 76.8 | H8: =(E8-192)-('Dati (2)'!A8-Parametri!$A$11)+Parametri!$A$2 -> 1255.5 | I8: =F8 -> 0.11547005 | J8: =Parametri!$D$8 -> 0.11547005
A9: =A8+1 -> 277 | D9: =B9+2*E9 -> 3352 | E9: 1676 | F9: =IF(C9=0, Parametri!$D$8, ABS(B9-C9)/(2*SQRT(3))) -> 0.11547005 | G9: =(A9-335)+135.8+(Parametri!$A$5/2) -> 77.8 | H9: =(E9-192)-('Dati (2)'!A9-Parametri!$A$11)+Parametri!$A$2 -> 1207 | I9: =F9 -> 0.11547005 | J9: =Parametri!$D$8 -> 0.11547005
A10: =A9+1 -> 278 | D10: =B10+2*E10 -> 3320 | E10: 1660 | F10: =IF(C10=0, Parametri!$D$8, ABS(B10-C10)/(2*SQRT(3))) -> 0.11547005 | G10: =(A10-335)+135.8+(Parametri!$A$5/2) -> 78.8 | H10: =(E10-192)-('Dati (2)'!A10-Parametri!$A$11)+Parametri!$A$2 -> 1190 | I10: =F10 -> 0.11547005 | J10: =Parametri!$D$8 -> 0.11547005
A11: =A10+1 -> 279 | D11: =B11+2*E11 -> 3231 | E11: 1615.5 | F11: =IF(C11=0, Parametri!$D$8, ABS(B11-C11)/(2*SQRT(3))) -> 0.11547005 | G11: =(A11-335)+135.8+(Parametri!$A$5/2) -> 79.8 | H11: =(E11-192)-('Dati (2)'!A11-Parametri!$A$11)+Parametri!$A$2 -> 1144.5 | I11: =F11 -> 0.11547005 | J11: =Parametri!$D$8 -> 0.11547005
A12: =A11+1 -> 280 | D12: =B12+2*E12 -> 3163 | E12: 1581.5 | F12: =IF(C12=0, Parametri!$D$8, ABS(B12-C12)/(2*SQRT(3))) -> 0.11547005 | G12: =(A12-335)+135.8+(Parametri!$A$5/2) -> 80.8 | H12: =(E12-192)-('Dati (2)'!A12-Parametri!$A$11)+Parametri!$A$2 -> 1109.5 | I12: =F12 -> 0.11547005 | J12: =Parametri!$D$8 -> 0.11547005
A13: =A12+1 -> 281 | D13: =B13+2*E13 -> 3122 | E13: 1561 | F13: =IF(C13=0, Parametri!$D$8, ABS(B13-C13)/(2*SQRT(3))) -> 0.11547005 | G13: =(A13-335)+135.8+(Parametri!$A$5/2) -> 81.8 | H13: =(E13-192)-('Dati (2)'!A13-Parametri!$A$11)+Parametri!$A$2 -> 1088 | I13: =F13 -> 0.11547005 | J13: =Parametri!$D$8 -> 0.11547005
A14: =A13+1 -> 282 | D14: =B14+2*E14 -> 3067 | E14: 1533.5 | F14: =IF(C14=0, Parametri!$D$8, ABS(B14-C14)/(2*SQRT(3))) -> 0.11547005 | G14: =(A14-335)+135.8+(Parametri!$A$5/2) -> 82.8 | H14: =(E14-192)-('Dati (2)'!A14-Parametri!$A$11)+Parametri!$A$2 -> 1059.5 | I14: =F14 -> 0.11547005 | J14: =Parametri!$D$8 -> 0.11547005
... A47: =A46+1 -> 315 | D47: =B47+2*E47 -> 2150 | E47: 1075 | F47: =IF(C47=0, Parametri!$D$8, ABS(B47-C47)/(2*SQRT(3))) -> 0.11547005 | G47: =(A47-335)+135.8+(Parametri!$A$5/2) -> 115.8 | H47: =(E47-192)-('Dati (2)'!A47-Parametri!$A$11)+Parametri!$A$2 -> 568 | I47: =F47 -> 0.11547005 | J47: =Parametri!$D$8 -> 0.11547005
A48: =A47+2 -> 317 | D48: =B48+2*E48 -> 2126 | E48: 1063 | F48: =IF(C48=0, Parametri!$D$8, ABS(B48-C48)/(2*SQRT(3))) -> 0.11547005 | G48: =(A48-335)+135.8+(Parametri!$A$5/2) -> 117.8 | H48: =(E48-192)-('Dati (2)'!A48-Parametri!$A$11)+Parametri!$A$2 -> 554 | I48: =F48 -> 0.11547005 | J48: =Parametri!$D$8 -> 0.11547005
A49: =A48+2 -> 319 | D49: =B49+2*E49 -> 2085 | E49: 1042.5 | F49: =IF(C49=0, Parametri!$D$8, ABS(B49-C49)/(2*SQRT(3))) -> 0.11547005 | G49: =(A49-335)+135.8+(Parametri!$A$5/2) -> 119.8 | H49: =(E49-192)-('Dati (2)'!A49-Parametri!$A$11)+Parametri!$A$2 -> 531.5 | I49: =F49 -> 0.11547005 | J49: =Parametri!$D$8 -> 0.11547005
A50: =A49+2 -> 321 | D50: =B50+2*E50 -> 2068 | E50: 1034 | F50: =IF(C50=0, Parametri!$D$8, ABS(B50-C50)/(2*SQRT(3))) -> 0.11547005 | G50: =(A50-335)+135.8+(Parametri!$A$5/2) -> 121.8 | H50: =(E50-192)-('Dati (2)'!A50-Parametri!$A$11)+Parametri!$A$2 -> 521 | I50: =F50 -> 0.11547005 | J50: =Parametri!$D$8 -> 0.11547005
A51: =A50+2 -> 323 | D51: =B51+2*E51 -> 2055 | E51: 1027.5 | F51: =IF(C51=0, Parametri!$D$8, ABS(B51-C51)/(2*SQRT(3))) -> 0.11547005 | G51: =(A51-335)+135.8+(Parametri!$A$5/2) -> 123.8 | H51: =(E51-192)-('Dati (2)'!A51-Parametri!$A$11)+Parametri!$A$2 -> 512.5 | I51: =F51 -> 0.11547005 | J51: =Parametri!$D$8 -> 0.11547005
A52: =A51+2 -> 325 | D52: =B52+2*E52 -> 2020 | E52: 1010 | F52: =IF(C52=0, Parametri!$D$8, ABS(B52-C52)/(2*SQRT(3))) -> 0.11547005 | G52: =(A52-335)+135.8+(Parametri!$A$5/2) -> 125.8 | H52: =(E52-192)-('Dati (2)'!A52-Parametri!$A$11)+Parametri!$A$2 -> 493 | I52: =F52 -> 0.11547005 | J52: =Parametri!$D$8 -> 0.11547005
A53: =A52+2 -> 327 | D53: =B53+2*E53 -> 1999 | E53: 999.5 | F53: =IF(C53=0, Parametri!$D$8, ABS(B53-C53)/(2*SQRT(3))) -> 0.11547005 | G53: =(A53-335)+135.8+(Parametri!$A$5/2) -> 127.8 | H53: =(E53-192)-('Dati (2)'!A53-Parametri!$A$11)+Parametri!$A$2 -> 480.5 | I53: =F53 -> 0.11547005 | J53: =Parametri!$D$8 -> 0.11547005
A54: =A53+2 -> 329 | D54: =B54+2*E54 -> 1975 | E54: 987.5 | F54: =IF(C54=0, Parametri!$D$8, ABS(B54-C54)/(2*SQRT(3))) -> 0.11547005 | G54: =(A54-335)+135.8+(Parametri!$A$5/2) -> 129.8 | H54: =(E54-192)-('Dati (2)'!A54-Parametri!$A$11)+Parametri!$A$2 -> 466.5 | I54: =F54 -> 0.11547005 | J54: =Parametri!$D$8 -> 0.11547005
A55: =A54+2 -> 331 | D55: =B55+2*E55 -> 1961 | E55: 980.5 | F55: =IF(C55=0, Parametri!$D$8, ABS(B55-C55)/(2*SQRT(3))) -> 0.11547005 | G55: =(A55-335)+135.8+(Parametri!$A$5/2) -> 131.8 | H55: =(E55-192)-('Dati (2)'!A55-Parametri!$A$11)+Parametri!$A$2 -> 457.5 | I55: =F55 -> 0.11547005 | J55: =Parametri!$D$8 -> 0.11547005
A56: =A55+2 -> 333 | D56: =B56+2*E56 -> 1940 | E56: 970 | F56: =IF(C56=0, Parametri!$D$8, ABS(B56-C56)/(2*SQRT(3))) -> 0.11547005 | G56: =(A56-335)+135.8+(Parametri!$A$5/2) -> 133.8 | H56: =(E56-192)-('Dati (2)'!A56-Parametri!$A$11)+Parametri!$A$2 -> 445 | I56: =F56 -> 0.11547005 | J56: =Parametri!$D$8 -> 0.11547005
A57: =A56+2 -> 335 | D57: =B57+2*E57 -> 1910 | E57: 955 | F57: =IF(C57=0, Parametri!$D$8, ABS(B57-C57)/(2*SQRT(3))) -> 0.11547005 | G57: =(A57-335)+135.8+(Parametri!$A$5/2) -> 135.8 | H57: =(E57-192)-('Dati (2)'!A57-Parametri!$A$11)+Parametri!$A$2 -> 428 | I57: =F57 -> 0.11547005 | J57: =Parametri!$D$8 -> 0.11547005
A58: =A57+2 -> 337 | D58: =B58+2*E58 -> 1891 | E58: 945.5 | F58: =IF(C58=0, Parametri!$D$8, ABS(B58-C58)/(2*SQRT(3))) -> 0.11547005 | G58: =(A58-335)+135.8+(Parametri!$A$5/2) -> 137.8 | H58: =(E58-192)-('Dati (2)'!A58-Parametri!$A$11)+Parametri!$A$2 -> 416.5 | I58: =F58 -> 0.11547005 | J58: =Parametri!$D$8 -> 0.11547005
A59: =A58+2 -> 339 | D59: =B59+2*E59 -> 1887 | E59: 943.5 | F59: =IF(C59=0, Parametri!$D$8, ABS(B59-C59)/(2*SQRT(3))) -> 0.11547005 | G59: =(A59-335)+135.8+(Parametri!$A$5/2) -> 139.8 | H59: =(E59-192)-('Dati (2)'!A59-Parametri!$A$11)+Parametri!$A$2 -> 412.5 | I59: =F59 -> 0.11547005 | J59: =Parametri!$D$8 -> 0.11547005
... A65: =A64+2 -> 351 | D65: =B65+2*E65 -> 1812 | E65: 906 | F65: =IF(C65=0, Parametri!$D$8, ABS(B65-C65)/(2*SQRT(3))) -> 0.11547005 | G65: =(A65-335)+135.8+(Parametri!$A$5/2) -> 151.8 | H65: =(E65-192)-('Dati (2)'!A65-Parametri!$A$11)+Parametri!$A$2 -> 363 | I65: =F65 -> 0.11547005 | J65: =Parametri!$D$8 -> 0.11547005
A66: =A65+3 -> 354 | D66: =B66+2*E66 -> 1806 | E66: 903 | F66: =IF(C66=0, Parametri!$D$8, ABS(B66-C66)/(2*SQRT(3))) -> 0.11547005 | G66: =(A66-335)+135.8+(Parametri!$A$5/2) -> 154.8 | H66: =(E66-192)-('Dati (2)'!A66-Parametri!$A$11)+Parametri!$A$2 -> 357 | I66: =F66 -> 0.11547005 | J66: =Parametri!$D$8 -> 0.11547005
A67: =A66+3 -> 357 | D67: =B67+2*E67 -> 1782 | E67: 891 | F67: =IF(C67=0, Parametri!$D$8, ABS(B67-C67)/(2*SQRT(3))) -> 0.11547005 | G67: =(A67-335)+135.8+(Parametri!$A$5/2) -> 157.8 | H67: =(E67-192)-('Dati (2)'!A67-Parametri!$A$11)+Parametri!$A$2 -> 342 | I67: =F67 -> 0.11547005 | J67: =Parametri!$D$8 -> 0.11547005
A68: =A67+3 -> 360 | D68: =B68+2*E68 -> 1777 | E68: 888.5 | F68: =IF(C68=0, Parametri!$D$8, ABS(B68-C68)/(2*SQRT(3))) -> 0.11547005 | G68: =(A68-335)+135.8+(Parametri!$A$5/2) -> 160.8 | H68: =(E68-192)-('Dati (2)'!A68-Parametri!$A$11)+Parametri!$A$2 -> 336.5 | I68: =F68 -> 0.11547005 | J68: =Parametri!$D$8 -> 0.11547005
A69: =A68+3 -> 363 | D69: =B69+2*E69 -> 1780 | E69: 890 | F69: =IF(C69=0, Parametri!$D$8, ABS(B69-C69)/(2*SQRT(3))) -> 0.11547005 | G69: =(A69-335)+135.8+(Parametri!$A$5/2) -> 163.8 | H69: =(E69-192)-('Dati (2)'!A69-Parametri!$A$11)+Parametri!$A$2 -> 335 | I69: =F69 -> 0.11547005 | J69: =Parametri!$D$8 -> 0.11547005
A70: =A69+3 -> 366 | D70: =B70+2*E70 -> 1752 | E70: 876 | F70: =IF(C70=0, Parametri!$D$8, ABS(B70-C70)/(2*SQRT(3))) -> 0.11547005 | G70: =(A70-335)+135.8+(Parametri!$A$5/2) -> 166.8 | H70: =(E70-192)-('Dati (2)'!A70-Parametri!$A$11)+Parametri!$A$2 -> 318 | I70: =F70 -> 0.11547005 | J70: =Parametri!$D$8 -> 0.11547005
A71: =A70+3 -> 369 | D71: =B71+2*E71 -> 1744 | E71: 872 | F71: =IF(C71=0, Parametri!$D$8, ABS(B71-C71)/(2*SQRT(3))) -> 0.11547005 | G71: =(A71-335)+135.8+(Parametri!$A$5/2) -> 169.8 | H71: =(E71-192)-('Dati (2)'!A71-Parametri!$A$11)+Parametri!$A$2 -> 311 | I71: =F71 -> 0.11547005 | J71: =Parametri!$D$8 -> 0.11547005
A72: =A71+3 -> 372 | D72: =B72+2*E72 -> 1742 | E72: 871 | F72: =IF(C72=0, Parametri!$D$8, ABS(B72-C72)/(2*SQRT(3))) -> 0.11547005 | G72: =(A72-335)+135.8+(Parametri!$A$5/2) -> 172.8 | H72: =(E72-192)-('Dati (2)'!A72-Parametri!$A$11)+Parametri!$A$2 -> 307 | I72: =F72 -> 0.11547005 | J72: =Parametri!$D$8 -> 0.11547005
A73: =A72+3 -> 375 | D73: =B73+2*E73 -> 1734 | E73: 867 | F73: =IF(C73=0, Parametri!$D$8, ABS(B73-C73)/(2*SQRT(3))) -> 0.11547005 | G73: =(A73-335)+135.8+(Parametri!$A$5/2) -> 175.8 | H73: =(E73-192)-('Dati (2)'!A73-Parametri!$A$11)+Parametri!$A$2 -> 300 | I73: =F73 -> 0.11547005 | J73: =Parametri!$D$8 -> 0.11547005
A74: =A73+4 -> 379 | D74: =B74+2*E74 -> 1721 | E74: 860.5 | F74: =IF(C74=0, Parametri!$D$8, ABS(B74-C74)/(2*SQRT(3))) -> 0.11547005 | G74: =(A74-335)+135.8+(Parametri!$A$5/2) -> 179.8 | H74: =(E74-192)-('Dati (2)'!A74-Parametri!$A$11)+Parametri!$A$2 -> 289.5 | I74: =F74 -> 0.11547005 | J74: =Parametri!$D$8 -> 0.11547005
A75: =A74+4 -> 383 | D75: =B75+2*E75 -> 1720 | E75: 860 | F75: =IF(C75=0, Parametri!$D$8, ABS(B75-C75)/(2*SQRT(3))) -> 0.11547005 | G75: =(A75-335)+135.8+(Parametri!$A$5/2) -> 183.8 | H75: =(E75-192)-('Dati (2)'!A75-Parametri!$A$11)+Parametri!$A$2 -> 285 | I75: =F75 -> 0.11547005 | J75: =Parametri!$D$8 -> 0.11547005
A76: =A75+4 -> 387 | D76: =B76+2*E76 -> 1706 | E76: 853 | F76: =IF(C76=0, Parametri!$D$8, ABS(B76-C76)/(2*SQRT(3))) -> 0.11547005 | G76: =(A76-335)+135.8+(Parametri!$A$5/2) -> 187.8 | H76: =(E76-192)-('Dati (2)'!A76-Parametri!$A$11)+Parametri!$A$2 -> 274 | I76: =F76 -> 0.11547005 | J76: =Parametri!$D$8 -> 0.11547005
A77: =A76+4 -> 391 | D77: =B77+2*E77 -> 1695 | E77: 847.5 | F77: =IF(C77=0, Parametri!$D$8, ABS(B77-C77)/(2*SQRT(3))) -> 0.11547005 | G77: =(A77-335)+135.8+(Parametri!$A$5/2) -> 191.8 | H77: =(E77-192)-('Dati (2)'!A77-Parametri!$A$11)+Parametri!$A$2 -> 264.5 | I77: =F77 -> 0.11547005 | J77: =Parametri!$D$8 -> 0.11547005
...

Sheet Dati
A1: x | B1: y_min | C1: y_max | D1: y_max2 | E1: y | F1: sigma_y | G1: p | H1: q | I1: sigma_p | J1: sigma_q
A2: 270 | D2: =B2+2*E2 -> 0 | E2: {=IF(C2=0, B2, MEAN(B2:C2))} -> 0 | F2: =IF(C2=0, Parametri!$D$8, ABS(B2-C2)/(2*SQRT(3))) -> 0.11547005 | G2: =(A2-Parametri!$A$11)+Parametri!$A$2+(Parametri!$A$5/2) -> 270 | H2: =(E2-Parametri!$A$8)-(Dati!A2-Parametri!$A$11)+Parametri!$A$2 -> -270 | I2: =F2 -> 0.11547005 | J2: =Parametri!$D$8 -> 0.11547005
A3: =A2+1 -> 271 | D3: =B3+2*E3 -> 0 | E3: {=IF(C3=0, B3, MEAN(B3:C3))} -> 0 | F3: =IF(C3=0, Parametri!$D$8, ABS(B3-C3)/(2*SQRT(3))) -> 0.11547005 | G3: =(A3-Parametri!$A$11)+Parametri!$A$2+(Parametri!$A$5/2) -> 271 | H3: =(E3-Parametri!$A$8)-(Dati!A3-Parametri!$A$11)+Parametri!$A$2 -> -271 | I3: =F3 -> 0.11547005 | J3: =Parametri!$D$8 -> 0.11547005
A4: =A3+1 -> 272 | D4: =B4+2*E4 -> 0 | E4: {=IF(C4=0, B4, MEAN(B4:C4))} -> 0 | F4: =IF(C4=0, Parametri!$D$8, ABS(B4-C4)/(2*SQRT(3))) -> 0.11547005 | G4: =(A4-Parametri!$A$11)+Parametri!$A$2+(Parametri!$A$5/2) -> 272 | H4: =(E4-Parametri!$A$8)-(Dati!A4-Parametri!$A$11)+Parametri!$A$2 -> -272 | I4: =F4 -> 0.11547005 | J4: =Parametri!$D$8 -> 0.11547005
A5: =A4+1 -> 273 | D5: =B5+2*E5 -> 0 | E5: {=IF(C5=0, B5, MEAN(B5:C5))} -> 0 | F5: =IF(C5=0, Parametri!$D$8, ABS(B5-C5)/(2*SQRT(3))) -> 0.11547005 | G5: =(A5-Parametri!$A$11)+Parametri!$A$2+(Parametri!$A$5/2) -> 273 | H5: =(E5-Parametri!$A$8)-(Dati!A5-Parametri!$A$11)+Parametri!$A$2 -> -273 | I5: =F5 -> 0.11547005 | J5: =Parametri!$D$8 -> 0.11547005
A6: =A5+1 -> 274 | D6: =B6+2*E6 -> 0 | E6: {=IF(C6=0, B6, MEAN(B6:C6))} -> 0 | F6: =IF(C6=0, Parametri!$D$8, ABS(B6-C6)/(2*SQRT(3))) -> 0.11547005 | G6: =(A6-Parametri!$A$11)+Parametri!$A$2+(Parametri!$A$5/2) -> 274 | H6: =(E6-Parametri!$A$8)-(Dati!A6-Parametri!$A$11)+Parametri!$A$2 -> -274 | I6: =F6 -> 0.11547005 | J6: =Parametri!$D$8 -> 0.11547005
A7: =A6+1 -> 275 | D7: =B7+2*E7 -> 0 | E7: {=IF(C7=0, B7, MEAN(B7:C7))} -> 0 | F7: =IF(C7=0, Parametri!$D$8, ABS(B7-C7)/(2*SQRT(3))) -> 0.11547005 | G7: =(A7-Parametri!$A$11)+Parametri!$A$2+(Parametri!$A$5/2) -> 275 | H7: =(E7-Parametri!$A$8)-(Dati!A7-Parametri!$A$11)+Parametri!$A$2 -> -275 | I7: =F7 -> 0.11547005 | J7: =Parametri!$D$8 -> 0.11547005
A8: =A7+1 -> 276 | D8: =B8+2*E8 -> 0 | E8: {=IF(C8=0, B8, MEAN(B8:C8))} -> 0 | F8: =IF(C8=0, Parametri!$D$8, ABS(B8-C8)/(2*SQRT(3))) -> 0.11547005 | G8: =(A8-Parametri!$A$11)+Parametri!$A$2+(Parametri!$A$5/2) -> 276 | H8: =(E8-Parametri!$A$8)-(Dati!A8-Parametri!$A$11)+Parametri!$A$2 -> -276 | I8: =F8 -> 0.11547005 | J8: =Parametri!$D$8 -> 0.11547005
A9: =A8+1 -> 277 | D9: =B9+2*E9 -> 0 | E9: {=IF(C9=0, B9, MEAN(B9:C9))} -> 0 | F9: =IF(C9=0, Parametri!$D$8, ABS(B9-C9)/(2*SQRT(3))) -> 0.11547005 | G9: =(A9-Parametri!$A$11)+Parametri!$A$2+(Parametri!$A$5/2) -> 277 | H9: =(E9-Parametri!$A$8)-(Dati!A9-Parametri!$A$11)+Parametri!$A$2 -> -277 | I9: =F9 -> 0.11547005 | J9: =Parametri!$D$8 -> 0.11547005
A10: =A9+1 -> 278 | D10: =B10+2*E10 -> 0 | E10: {=IF(C10=0, B10, MEAN(B10:C10))} -> 0 | F10: =IF(C10=0, Parametri!$D$8, ABS(B10-C10)/(2*SQRT(3))) -> 0.11547005 | G10: =(A10-Parametri!$A$11)+Parametri!$A$2+(Parametri!$A$5/2) -> 278 | H10: =(E10-Parametri!$A$8)-(Dati!A10-Parametri!$A$11)+Parametri!$A$2 -> -278 | I10: =F10 -> 0.11547005 | J10: =Parametri!$D$8 -> 0.11547005
A11: =A10+1 -> 279 | D11: =B11+2*E11 -> 0 | E11: {=IF(C11=0, B11, MEAN(B11:C11))} -> 0 | F11: =IF(C11=0, Parametri!$D$8, ABS(B11-C11)/(2*SQRT(3))) -> 0.11547005 | G11: =(A11-Parametri!$A$11)+Parametri!$A$2+(Parametri!$A$5/2) -> 279 | H11: =(E11-Parametri!$A$8)-(Dati!A11-Parametri!$A$11)+Parametri!$A$2 -> -279 | I11: =F11 -> 0.11547005 | J11: =Parametri!$D$8 -> 0.11547005
A12: =A11+1 -> 280 | D12: =B12+2*E12 -> 0 | E12: {=IF(C12=0, B12, MEAN(B12:C12))} -> 0 | F12: =IF(C12=0, Parametri!$D$8, ABS(B12-C12)/(2*SQRT(3))) -> 0.11547005 | G12: =(A12-Parametri!$A$11)+Parametri!$A$2+(Parametri!$A$5/2) -> 280 | H12: =(E12-Parametri!$A$8)-(Dati!A12-Parametri!$A$11)+Parametri!$A$2 -> -280 | I12: =F12 -> 0.11547005 | J12: =Parametri!$D$8 -> 0.11547005
A13: =A12+1 -> 281 | D13: =B13+2*E13 -> 0 | E13: {=IF(C13=0, B13, MEAN(B13:C13))} -> 0 | F13: =IF(C13=0, Parametri!$D$8, ABS(B13-C13)/(2*SQRT(3))) -> 0.11547005 | G13: =(A13-Parametri!$A$11)+Parametri!$A$2+(Parametri!$A$5/2) -> 281 | H13: =(E13-Parametri!$A$8)-(Dati!A13-Parametri!$A$11)+Parametri!$A$2 -> -281 | I13: =F13 -> 0.11547005 | J13: =Parametri!$D$8 -> 0.11547005
A14: =A13+1 -> 282 | D14: =B14+2*E14 -> 0 | E14: {=IF(C14=0, B14, MEAN(B14:C14))} -> 0 | F14: =IF(C14=0, Parametri!$D$8, ABS(B14-C14)/(2*SQRT(3))) -> 0.11547005 | G14: =(A14-Parametri!$A$11)+Parametri!$A$2+(Parametri!$A$5/2) -> 282 | H14: =(E14-Parametri!$A$8)-(Dati!A14-Parametri!$A$11)+Parametri!$A$2 -> -282 | I14: =F14 -> 0.11547005 | J14: =Parametri!$D$8 -> 0.11547005
... A47: =A46+1 -> 315 | D47: =B47+2*E47 -> 0 | E47: {=IF(C47=0, B47, MEAN(B47:C47))} -> 0 | F47: =IF(C47=0, Parametri!$D$8, ABS(B47-C47)/(2*SQRT(3))) -> 0.11547005 | G47: =(A47-Parametri!$A$11)+Parametri!$A$2+(Parametri!$A$5/2) -> 315 | H47: =(E47-Parametri!$A$8)-(Dati!A47-Parametri!$A$11)+Parametri!$A$2 -> -315 | I47: =F47 -> 0.11547005 | J47: =Parametri!$D$8 -> 0.11547005
A48: =A47+2 -> 317 | D48: =B48+2*E48 -> 0 | E48: {=IF(C48=0, B48, MEAN(B48:C48))} -> 0 | F48: =IF(C48=0, Parametri!$D$8, ABS(B48-C48)/(2*SQRT(3))) -> 0.11547005 | G48: =(A48-Parametri!$A$11)+Parametri!$A$2+(Parametri!$A$5/2) -> 317 | H48: =(E48-Parametri!$A$8)-(Dati!A48-Parametri!$A$11)+Parametri!$A$2 -> -317 | I48: =F48 -> 0.11547005 | J48: =Parametri!$D$8 -> 0.11547005
A49: =A48+2 -> 319 | D49: =B49+2*E49 -> 0 | E49: {=IF(C49=0, B49, MEAN(B49:C49))} -> 0 | F49: =IF(C49=0, Parametri!$D$8, ABS(B49-C49)/(2*SQRT(3))) -> 0.11547005 | G49: =(A49-Parametri!$A$11)+Parametri!$A$2+(Parametri!$A$5/2) -> 319 | H49: =(E49-Parametri!$A$8)-(Dati!A49-Parametri!$A$11)+Parametri!$A$2 -> -319 | I49: =F49 -> 0.11547005 | J49: =Parametri!$D$8 -> 0.11547005
A50: =A49+2 -> 321 | D50: =B50+2*E50 -> 0 | E50: {=IF(C50=0, B50, MEAN(B50:C50))} -> 0 | F50: =IF(C50=0, Parametri!$D$8, ABS(B50-C50)/(2*SQRT(3))) -> 0.11547005 | G50: =(A50-Parametri!$A$11)+Parametri!$A$2+(Parametri!$A$5/2) -> 321 | H50: =(E50-Parametri!$A$8)-(Dati!A50-Parametri!$A$11)+Parametri!$A$2 -> -321 | I50: =F50 -> 0.11547005 | J50: =Parametri!$D$8 -> 0.11547005
A51: =A50+2 -> 323 | D51: =B51+2*E51 -> 0 | E51: {=IF(C51=0, B51, MEAN(B51:C51))} -> 0 | F51: =IF(C51=0, Parametri!$D$8, ABS(B51-C51)/(2*SQRT(3))) -> 0.11547005 | G51: =(A51-Parametri!$A$11)+Parametri!$A$2+(Parametri!$A$5/2) -> 323 | H51: =(E51-Parametri!$A$8)-(Dati!A51-Parametri!$A$11)+Parametri!$A$2 -> -323 | I51: =F51 -> 0.11547005 | J51: =Parametri!$D$8 -> 0.11547005
A52: =A51+2 -> 325 | D52: =B52+2*E52 -> 0 | E52: {=IF(C52=0, B52, MEAN(B52:C52))} -> 0 | F52: =IF(C52=0, Parametri!$D$8, ABS(B52-C52)/(2*SQRT(3))) -> 0.11547005 | G52: =(A52-Parametri!$A$11)+Parametri!$A$2+(Parametri!$A$5/2) -> 325 | H52: =(E52-Parametri!$A$8)-(Dati!A52-Parametri!$A$11)+Parametri!$A$2 -> -325 | I52: =F52 -> 0.11547005 | J52: =Parametri!$D$8 -> 0.11547005
A53: =A52+2 -> 327 | D53: =B53+2*E53 -> 0 | E53: {=IF(C53=0, B53, MEAN(B53:C53))} -> 0 | F53: =IF(C53=0, Parametri!$D$8, ABS(B53-C53)/(2*SQRT(3))) -> 0.11547005 | G53: =(A53-Parametri!$A$11)+Parametri!$A$2+(Parametri!$A$5/2) -> 327 | H53: =(E53-Parametri!$A$8)-(Dati!A53-Parametri!$A$11)+Parametri!$A$2 -> -327 | I53: =F53 -> 0.11547005 | J53: =Parametri!$D$8 -> 0.11547005
A54: =A53+2 -> 329 | D54: =B54+2*E54 -> 0 | E54: {=IF(C54=0, B54, MEAN(B54:C54))} -> 0 | F54: =IF(C54=0, Parametri!$D$8, ABS(B54-C54)/(2*SQRT(3))) -> 0.11547005 | G54: =(A54-Parametri!$A$11)+Parametri!$A$2+(Parametri!$A$5/2) -> 329 | H54: =(E54-Parametri!$A$8)-(Dati!A54-Parametri!$A$11)+Parametri!$A$2 -> -329 | I54: =F54 -> 0.11547005 | J54: =Parametri!$D$8 -> 0.11547005
A55: =A54+2 -> 331 | D55: =B55+2*E55 -> 0 | E55: {=IF(C55=0, B55, MEAN(B55:C55))} -> 0 | F55: =IF(C55=0, Parametri!$D$8, ABS(B55-C55)/(2*SQRT(3))) -> 0.11547005 | G55: =(A55-Parametri!$A$11)+Parametri!$A$2+(Parametri!$A$5/2) -> 331 | H55: =(E55-Parametri!$A$8)-(Dati!A55-Parametri!$A$11)+Parametri!$A$2 -> -331 | I55: =F55 -> 0.11547005 | J55: =Parametri!$D$8 -> 0.11547005
A56: =A55+2 -> 333 | D56: =B56+2*E56 -> 0 | E56: {=IF(C56=0, B56, MEAN(B56:C56))} -> 0 | F56: =IF(C56=0, Parametri!$D$8, ABS(B56-C56)/(2*SQRT(3))) -> 0.11547005 | G56: =(A56-Parametri!$A$11)+Parametri!$A$2+(Parametri!$A$5/2) -> 333 | H56: =(E56-Parametri!$A$8)-(Dati!A56-Parametri!$A$11)+Parametri!$A$2 -> -333 | I56: =F56 -> 0.11547005 | J56: =Parametri!$D$8 -> 0.11547005
A57: =A56+2 -> 335 | D57: =B57+2*E57 -> 0 | E57: {=IF(C57=0, B57, MEAN(B57:C57))} -> 0 | F57: =IF(C57=0, Parametri!$D$8, ABS(B57-C57)/(2*SQRT(3))) -> 0.11547005 | G57: =(A57-Parametri!$A$11)+Parametri!$A$2+(Parametri!$A$5/2) -> 335 | H57: =(E57-Parametri!$A$8)-(Dati!A57-Parametri!$A$11)+Parametri!$A$2 -> -335 | I57: =F57 -> 0.11547005 | J57: =Parametri!$D$8 -> 0.11547005
A58: =A57+2 -> 337 | D58: =B58+2*E58 -> 0 | E58: {=IF(C58=0, B58, MEAN(B58:C58))} -> 0 | F58: =IF(C58=0, Parametri!$D$8, ABS(B58-C58)/(2*SQRT(3))) -> 0.11547005 | G58: =(A58-Parametri!$A$11)+Parametri!$A$2+(Parametri!$A$5/2) -> 337 | H58: =(E58-Parametri!$A$8)-(Dati!A58-Parametri!$A$11)+Parametri!$A$2 -> -337 | I58: =F58 -> 0.11547005 | J58: =Parametri!$D$8 -> 0.11547005
A59: =A58+2 -> 339 | D59: =B59+2*E59 -> 0 | E59: {=IF(C59=0, B59, MEAN(B59:C59))} -> 0 | F59: =IF(C59=0, Parametri!$D$8, ABS(B59-C59)/(2*SQRT(3))) -> 0.11547005 | G59: =(A59-Parametri!$A$11)+Parametri!$A$2+(Parametri!$A$5/2) -> 339 | H59: =(E59-Parametri!$A$8)-(Dati!A59-Parametri!$A$11)+Parametri!$A$2 -> -339 | I59: =F59 -> 0.11547005 | J59: =Parametri!$D$8 -> 0.11547005
... A65: =A64+2 -> 351 | D65: =B65+2*E65 -> 0 | E65: {=IF(C65=0, B65, MEAN(B65:C65))} -> 0 | F65: =IF(C65=0, Parametri!$D$8, ABS(B65-C65)/(2*SQRT(3))) -> 0.11547005 | G65: =(A65-Parametri!$A$11)+Parametri!$A$2+(Parametri!$A$5/2) -> 351 | H65: =(E65-Parametri!$A$8)-(Dati!A65-Parametri!$A$11)+Parametri!$A$2 -> -351 | I65: =F65 -> 0.11547005 | J65: =Parametri!$D$8 -> 0.11547005
A66: =A65+3 -> 354 | D66: =B66+2*E66 -> 0 | E66: {=IF(C66=0, B66, MEAN(B66:C66))} -> 0 | F66: =IF(C66=0, Parametri!$D$8, ABS(B66-C66)/(2*SQRT(3))) -> 0.11547005 | G66: =(A66-Parametri!$A$11)+Parametri!$A$2+(Parametri!$A$5/2) -> 354 | H66: =(E66-Parametri!$A$8)-(Dati!A66-Parametri!$A$11)+Parametri!$A$2 -> -354 | I66: =F66 -> 0.11547005 | J66: =Parametri!$D$8 -> 0.11547005
A67: =A66+3 -> 357 | D67: =B67+2*E67 -> 0 | E67: {=IF(C67=0, B67, MEAN(B67:C67))} -> 0 | F67: =IF(C67=0, Parametri!$D$8, ABS(B67-C67)/(2*SQRT(3))) -> 0.11547005 | G67: =(A67-Parametri!$A$11)+Parametri!$A$2+(Parametri!$A$5/2) -> 357 | H67: =(E67-Parametri!$A$8)-(Dati!A67-Parametri!$A$11)+Parametri!$A$2 -> -357 | I67: =F67 -> 0.11547005 | J67: =Parametri!$D$8 -> 0.11547005
A68: =A67+3 -> 360 | D68: =B68+2*E68 -> 0 | E68: {=IF(C68=0, B68, MEAN(B68:C68))} -> 0 | F68: =IF(C68=0, Parametri!$D$8, ABS(B68-C68)/(2*SQRT(3))) -> 0.11547005 | G68: =(A68-Parametri!$A$11)+Parametri!$A$2+(Parametri!$A$5/2) -> 360 | H68: =(E68-Parametri!$A$8)-(Dati!A68-Parametri!$A$11)+Parametri!$A$2 -> -360 | I68: =F68 -> 0.11547005 | J68: =Parametri!$D$8 -> 0.11547005
A69: =A68+3 -> 363 | D69: =B69+2*E69 -> 0 | E69: {=IF(C69=0, B69, MEAN(B69:C69))} -> 0 | F69: =IF(C69=0, Parametri!$D$8, ABS(B69-C69)/(2*SQRT(3))) -> 0.11547005 | G69: =(A69-Parametri!$A$11)+Parametri!$A$2+(Parametri!$A$5/2) -> 363 | H69: =(E69-Parametri!$A$8)-(Dati!A69-Parametri!$A$11)+Parametri!$A$2 -> -363 | I69: =F69 -> 0.11547005 | J69: =Parametri!$D$8 -> 0.11547005
A70: =A69+3 -> 366 | D70: =B70+2*E70 -> 0 | E70: {=IF(C70=0, B70, MEAN(B70:C70))} -> 0 | F70: =IF(C70=0, Parametri!$D$8, ABS(B70-C70)/(2*SQRT(3))) -> 0.11547005 | G70: =(A70-Parametri!$A$11)+Parametri!$A$2+(Parametri!$A$5/2) -> 366 | H70: =(E70-Parametri!$A$8)-(Dati!A70-Parametri!$A$11)+Parametri!$A$2 -> -366 | I70: =F70 -> 0.11547005 | J70: =Parametri!$D$8 -> 0.11547005
A71: =A70+3 -> 369 | D71: =B71+2*E71 -> 0 | E71: {=IF(C71=0, B71, MEAN(B71:C71))} -> 0 | F71: =IF(C71=0, Parametri!$D$8, ABS(B71-C71)/(2*SQRT(3))) -> 0.11547005 | G71: =(A71-Parametri!$A$11)+Parametri!$A$2+(Parametri!$A$5/2) -> 369 | H71: =(E71-Parametri!$A$8)-(Dati!A71-Parametri!$A$11)+Parametri!$A$2 -> -369 | I71: =F71 -> 0.11547005 | J71: =Parametri!$D$8 -> 0.11547005
A72: =A71+3 -> 372 | D72: =B72+2*E72 -> 0 | E72: {=IF(C72=0, B72, MEAN(B72:C72))} -> 0 | F72: =IF(C72=0, Parametri!$D$8, ABS(B72-C72)/(2*SQRT(3))) -> 0.11547005 | G72: =(A72-Parametri!$A$11)+Parametri!$A$2+(Parametri!$A$5/2) -> 372 | H72: =(E72-Parametri!$A$8)-(Dati!A72-Parametri!$A$11)+Parametri!$A$2 -> -372 | I72: =F72 -> 0.11547005 | J72: =Parametri!$D$8 -> 0.11547005
A73: =A72+3 -> 375 | D73: =B73+2*E73 -> 0 | E73: {=IF(C73=0, B73, MEAN(B73:C73))} -> 0 | F73: =IF(C73=0, Parametri!$D$8, ABS(B73-C73)/(2*SQRT(3))) -> 0.11547005 | G73: =(A73-Parametri!$A$11)+Parametri!$A$2+(Parametri!$A$5/2) -> 375 | H73: =(E73-Parametri!$A$8)-(Dati!A73-Parametri!$A$11)+Parametri!$A$2 -> -375 | I73: =F73 -> 0.11547005 | J73: =Parametri!$D$8 -> 0.11547005
A74: =A73+4 -> 379 | D74: =B74+2*E74 -> 0 | E74: {=IF(C74=0, B74, MEAN(B74:C74))} -> 0 | F74: =IF(C74=0, Parametri!$D$8, ABS(B74-C74)/(2*SQRT(3))) -> 0.11547005 | G74: =(A74-Parametri!$A$11)+Parametri!$A$2+(Parametri!$A$5/2) -> 379 | H74: =(E74-Parametri!$A$8)-(Dati!A74-Parametri!$A$11)+Parametri!$A$2 -> -379 | I74: =F74 -> 0.11547005 | J74: =Parametri!$D$8 -> 0.11547005
A75: =A74+4 -> 383 | D75: =B75+2*E75 -> 0 | E75: {=IF(C75=0, B75, MEAN(B75:C75))} -> 0 | F75: =IF(C75=0, Parametri!$D$8, ABS(B75-C75)/(2*SQRT(3))) -> 0.11547005 | G75: =(A75-Parametri!$A$11)+Parametri!$A$2+(Parametri!$A$5/2) -> 383 | H75: =(E75-Parametri!$A$8)-(Dati!A75-Parametri!$A$11)+Parametri!$A$2 -> -383 | I75: =F75 -> 0.11547005 | J75: =Parametri!$D$8 -> 0.11547005
A76: =A75+4 -> 387 | D76: =B76+2*E76 -> 0 | E76: {=IF(C76=0, B76, MEAN(B76:C76))} -> 0 | F76: =IF(C76=0, Parametri!$D$8, ABS(B76-C76)/(2*SQRT(3))) -> 0.11547005 | G76: =(A76-Parametri!$A$11)+Parametri!$A$2+(Parametri!$A$5/2) -> 387 | H76: =(E76-Parametri!$A$8)-(Dati!A76-Parametri!$A$11)+Parametri!$A$2 -> -387 | I76: =F76 -> 0.11547005 | J76: =Parametri!$D$8 -> 0.11547005
A77: =A76+4 -> 391 | D77: =B77+2*E77 -> 0 | E77: {=IF(C77=0, B77, MEAN(B77:C77))} -> 0 | F77: =IF(C77=0, Parametri!$D$8, ABS(B77-C77)/(2*SQRT(3))) -> 0.11547005 | G77: =(A77-Parametri!$A$11)+Parametri!$A$2+(Parametri!$A$5/2) -> 391 | H77: =(E77-Parametri!$A$8)-(Dati!A77-Parametri!$A$11)+Parametri!$A$2 -> -391 | I77: =F77 -> 0.11547005 | J77: =Parametri!$D$8 -> 0.11547005
...
