Workbook

Sheet Parametri
A1: L | B1: err_L | C1: sigma_L
A2: 104 | B2: =1/20 -> 0.05 | C2: =B5/SQRT(3) -> 0.028867513
A4: D | B4: err_D | C4: sigma_D
A5: 17 | B5: =1/20 -> 0.05 | C5: =B5/SQRT(3) -> 0.028867513
A7: y_0 | B7: err_y0 | C7: sigma_y0 | D7: sigma_y
A8: 237 | B8: 0.2 | C8: =B8/SQRT(3) -> 0.11547005 | D8: =B8/SQRT(3) -> 0.11547005
A10: x_0 | B10: err_x0 | C10: sigma_x0 | D10: sigma_x
A11: 131 | B11: 0.2 | C11: =B11/SQRT(3) -> 0.11547005 | D11: =B11/SQRT(3) -> 0.11547005

Sheet Dati
A1: x | B1: y_min | C1: y_max | D1: y | E1: sigma_y | F1: p | G1: q | H1: sigma_p | I1: sigma_q
A2: 251 | B2: 1802 | C2: 1841 | D2: =IF(C2=0, B2, GEOMEAN(B2:C2)) -> 1821.3956 | E2: =MAX(Parametri!$D$8, ABS(B2-C2)/(2*SQRT(3))) -> 11.25833 | F2: =(A2-Parametri!$A$11)+Parametri!$A$2+(Parametri!$A$5/2) -> 232.5 | G2: =(D2-Parametri!$A$8)-(A2-Parametri!$A$11)+Parametri!$A$2 -> 1568.3956 | H2: =E2 -> 11.25833 | I2: =Parametri!$D$8 -> 0.11547005 | K2: =C2-B2 -> 39 | L2: FONTE DI ERRORE | U2: 0 | V2: 0
A3: =A2+1 -> 252 | B3: 1719 | C3: 1836 | D3: =IF(C3=0, B3, GEOMEAN(B3:C3)) -> 1776.5371 | E3: =MAX(Parametri!$D$8, ABS(B3-C3)/(2*SQRT(3))) -> 33.774991 | F3: =(A3-Parametri!$A$11)+Parametri!$A$2+(Parametri!$A$5/2) -> 233.5 | G3: =(D3-Parametri!$A$8)-(A3-Parametri!$A$11)+Parametri!$A$2 -> 1522.5371 | H3: =E3 -> 33.774991 | I3: =Parametri!$D$8 -> 0.11547005 | K3: =C3-B3 -> 117 | L3: modifica messa a fuoco fonte di errore dovuta al generatore | U3: 2000 | V3: 2000
A4: =A3+1 -> 253 | B4: 1690 | C4: 1853 | D4: =IF(C4=0, B4, GEOMEAN(B4:C4)) -> 1769.6243 | E4: =MAX(Parametri!$D$8, ABS(B4-C4)/(2*SQRT(3))) -> 47.054047 | F4: =(A4-Parametri!$A$11)+Parametri!$A$2+(Parametri!$A$5/2) -> 234.5 | G4: =(D4-Parametri!$A$8)-(A4-Parametri!$A$11)+Parametri!$A$2 -> 1514.6243 | H4: =E4 -> 47.054047 | I4: =Parametri!$D$8 -> 0.11547005 | K4: =C4-B4 -> 163
A5: =A4+1 -> 254 | B5: 1630 | C5: 1782 | D5: =IF(C5=0, B5, GEOMEAN(B5:C5)) -> 1704.3063 | E5: =MAX(Parametri!$D$8, ABS(B5-C5)/(2*SQRT(3))) -> 43.87862 | F5: =(A5-Parametri!$A$11)+Parametri!$A$2+(Parametri!$A$5/2) -> 235.5 | G5: =(D5-Parametri!$A$8)-(A5-Parametri!$A$11)+Parametri!$A$2 -> 1448.3063 | H5: =E5 -> 43.87862 | I5: =Parametri!$D$8 -> 0.11547005 | K5: =C5-B5 -> 152
A6: =A5+1 -> 255 | B6: 1605 | C6: 1745 | D6: =IF(C6=0, B6, GEOMEAN(B6:C6)) -> 1673.5367 | E6: =MAX(Parametri!$D$8, ABS(B6-C6)/(2*SQRT(3))) -> 40.414519 | F6: =(A6-Parametri!$A$11)+Parametri!$A$2+(Parametri!$A$5/2) -> 236.5 | G6: =(D6-Parametri!$A$8)-(A6-Parametri!$A$11)+Parametri!$A$2 -> 1416.5367 | H6: =E6 -> 40.414519 | I6: =Parametri!$D$8 -> 0.11547005 | K6: =C6-B6 -> 140
A7: =A6+1 -> 256 | B7: 1574 | C7: 1710 | D7: =IF(C7=0, B7, GEOMEAN(B7:C7)) -> 1640.5914 | E7: =MAX(Parametri!$D$8, ABS(B7-C7)/(2*SQRT(3))) -> 39.259818 | F7: =(A7-Parametri!$A$11)+Parametri!$A$2+(Parametri!$A$5/2) -> 237.5 | G7: =(D7-Parametri!$A$8)-(A7-Parametri!$A$11)+Parametri!$A$2 -> 1382.5914 | H7: =E7 -> 39.259818 | I7: =Parametri!$D$8 -> 0.11547005 | K7: =C7-B7 -> 136
A8: =A7+1 -> 257 | B8: 1546 | C8: 1679 | D8: =IF(C8=0, B8, GEOMEAN(B8:C8)) -> 1611.1282 | E8: =MAX(Parametri!$D$8, ABS(B8-C8)/(2*SQRT(3))) -> 38.393793 | F8: =(A8-Parametri!$A$11)+Parametri!$A$2+(Parametri!$A$5/2) -> 238.5 | G8: =(D8-Parametri!$A$8)-(A8-Parametri!$A$11)+Parametri!$A$2 -> 1352.1282 | H8: =E8 -> 38.393793 | I8: =Parametri!$D$8 -> 0.11547005 | K8: =C8-B8 -> 133
A9: =A8+1 -> 258 | B9: 1525 | C9: 1629 | D9: =IF(C9=0, B9, GEOMEAN(B9:C9)) -> 1576.1424 | E9: =MAX(Parametri!$D$8, ABS(B9-C9)/(2*SQRT(3))) -> 30.022214 | F9: =(A9-Parametri!$A$11)+Parametri!$A$2+(Parametri!$A$5/2) -> 239.5 | G9: =(D9-Parametri!$A$8)-(A9-Parametri!$A$11)+Parametri!$A$2 -> 1316.1424 | H9: =E9 -> 30.022214 | I9: =Parametri!$D$8 -> 0.11547005 | K9: =C9-B9 -> 104
A10: =A9+1 -> 259 | B10: 1505 | C10: 1603 | D10: =IF(C10=0, B10, GEOMEAN(B10:C10)) -> 1553.2273 | E10: =MAX(Parametri!$D$8, ABS(B10-C10)/(2*SQRT(3))) -> 28.290163 | F10: =(A10-Parametri!$A$11)+Parametri!$A$2+(Parametri!$A$5/2) -> 240.5 | G10: =(D10-Parametri!$A$8)-(A10-Parametri!$A$11)+Parametri!$A$2 -> 1292.2273 | H10: =E10 -> 28.290163 | I10: =Parametri!$D$8 -> 0.11547005 | K10: =C10-B10 -> 98
A11: =A10+1 -> 260 | B11: 1467 | C11: 1572 | D11: =IF(C11=0, B11, GEOMEAN(B11:C11)) -> 1518.5928 | E11: =MAX(Parametri!$D$8, ABS(B11-C11)/(2*SQRT(3))) -> 30.310889 | F11: =(A11-Parametri!$A$11)+Parametri!$A$2+(Parametri!$A$5/2) -> 241.5 | G11: =(D11-Parametri!$A$8)-(A11-Parametri!$A$11)+Parametri!$A$2 -> 1256.5928 | H11: =E11 -> 30.310889 | I11: =Parametri!$D$8 -> 0.11547005 | K11: =C11-B11 -> 105
A12: =A11+1 -> 261 | B12: 1452 | C12: 1534 | D12: =IF(C12=0, B12, GEOMEAN(B12:C12)) -> 1492.4369 | E12: =MAX(Parametri!$D$8, ABS(B12-C12)/(2*SQRT(3))) -> 23.671361 | F12: =(A12-Parametri!$A$11)+Parametri!$A$2+(Parametri!$A$5/2) -> 242.5 | G12: =(D12-Parametri!$A$8)-(A12-Parametri!$A$11)+Parametri!$A$2 -> 1229.4369 | H12: =E12 -> 23.671361 | I12: =Parametri!$D$8 -> 0.11547005 | K12: =C12-B12 -> 82
A13: =A12+1 -> 262 | B13: 1442 | C13: 1520 | D13: =IF(C13=0, B13, GEOMEAN(B13:C13)) -> 1480.4864 | E13: =MAX(Parametri!$D$8, ABS(B13-C13)/(2*SQRT(3))) -> 22.51666 | F13: =(A13-Parametri!$A$11)+Parametri!$A$2+(Parametri!$A$5/2) -> 243.5 | G13: =(D13-Parametri!$A$8)-(A13-Parametri!$A$11)+Parametri!$A$2 -> 1216.4864 | H13: =E13 -> 22.51666 | I13: =Parametri!$D$8 -> 0.11547005 | K13: =C13-B13 -> 78
A14: =A13+1 -> 263 | B14: 1402 | C14: 1485 | D14: =IF(C14=0, B14, GEOMEAN(B14:C14)) -> 1442.9033 | E14: =MAX(Parametri!$D$8, ABS(B14-C14)/(2*SQRT(3))) -> 23.960036 | F14: =(A14-Parametri!$A$11)+Parametri!$A$2+(Parametri!$A$5/2) -> 244.5 | G14: =(D14-Parametri!$A$8)-(A14-Parametri!$A$11)+Parametri!$A$2 -> 1177.9033 | H14: =E14 -> 23.960036 | I14: =Parametri!$D$8 -> 0.11547005 | K14: =C14-B14 -> 83
A15: =A14+1 -> 264 | B15: 1391 | C15: 1462 | D15: =IF(C15=0, B15, GEOMEAN(B15:C15)) -> 1426.0582 | E15: =MAX(Parametri!$D$8, ABS(B15-C15)/(2*SQRT(3))) -> 20.495935 | F15: =(A15-Parametri!$A$11)+Parametri!$A$2+(Parametri!$A$5/2) -> 245.5 | G15: =(D15-Parametri!$A$8)-(A15-Parametri!$A$11)+Parametri!$A$2 -> 1160.0582 | H15: =E15 -> 20.495935 | I15: =Parametri!$D$8 -> 0.11547005 | K15: =C15-B15 -> 71
... A35: =A34+1 -> 284 | B35: 1122 | C35: 1163 | D35: =IF(C35=0, B35, GEOMEAN(B35:C35)) -> 1142.3161 | E35: =MAX(Parametri!$D$8, ABS(B35-C35)/(2*SQRT(3))) -> 11.835681 | F35: =(A35-Parametri!$A$11)+Parametri!$A$2+(Parametri!$A$5/2) -> 265.5 | G35: =(D35-Parametri!$A$8)-(A35-Parametri!$A$11)+Parametri!$A$2 -> 856.31607 | H35: =E35 -> 11.835681 | I35: =Parametri!$D$8 -> 0.11547005 | K35: =C35-B35 -> 41
A36: =A35+2 -> 286 | B36: 1110 | C36: 1138 | D36: =IF(C36=0, B36, GEOMEAN(B36:C36)) -> 1123.9128 | E36: =MAX(Parametri!$D$8, ABS(B36-C36)/(2*SQRT(3))) -> 8.0829038 | F36: =(A36-Parametri!$A$11)+Parametri!$A$2+(Parametri!$A$5/2) -> 267.5 | G36: =(D36-Parametri!$A$8)-(A36-Parametri!$A$11)+Parametri!$A$2 -> 835.91281 | H36: =E36 -> 8.0829038 | I36: =Parametri!$D$8 -> 0.11547005 | K36: =C36-B36 -> 28
A37: =A36+2 -> 288 | B37: 1094 | C37: 1121 | D37: =IF(C37=0, B37, GEOMEAN(B37:C37)) -> 1107.4177 | E37: =MAX(Parametri!$D$8, ABS(B37-C37)/(2*SQRT(3))) -> 7.7942286 | F37: =(A37-Parametri!$A$11)+Parametri!$A$2+(Parametri!$A$5/2) -> 269.5 | G37: =(D37-Parametri!$A$8)-(A37-Parametri!$A$11)+Parametri!$A$2 -> 817.41772 | H37: =E37 -> 7.7942286 | I37: =Parametri!$D$8 -> 0.11547005 | K37: =C37-B37 -> 27
A38: =A37+2 -> 290 | B38: 1076 | C38: 1107 | D38: =IF(C38=0, B38, GEOMEAN(B38:C38)) -> 1091.3899 | E38: =MAX(Parametri!$D$8, ABS(B38-C38)/(2*SQRT(3))) -> 8.9489292 | F38: =(A38-Parametri!$A$11)+Parametri!$A$2+(Parametri!$A$5/2) -> 271.5 | G38: =(D38-Parametri!$A$8)-(A38-Parametri!$A$11)+Parametri!$A$2 -> 799.38994 | H38: =E38 -> 8.9489292 | I38: =Parametri!$D$8 -> 0.11547005 | K38: =C38-B38 -> 31
A39: =A38+2 -> 292 | B39: 1064 | C39: 1092 | D39: =IF(C39=0, B39, GEOMEAN(B39:C39)) -> 1077.9091 | E39: =MAX(Parametri!$D$8, ABS(B39-C39)/(2*SQRT(3))) -> 8.0829038 | F39: =(A39-Parametri!$A$11)+Parametri!$A$2+(Parametri!$A$5/2) -> 273.5 | G39: =(D39-Parametri!$A$8)-(A39-Parametri!$A$11)+Parametri!$A$2 -> 783.90909 | H39: =E39 -> 8.0829038 | I39: =Parametri!$D$8 -> 0.11547005 | K39: =C39-B39 -> 28
A40: =A39+2 -> 294 | B40: 1048 | C40: 1079 | D40: =IF(C40=0, B40, GEOMEAN(B40:C40)) -> 1063.387 | E40: =MAX(Parametri!$D$8, ABS(B40-C40)/(2*SQRT(3))) -> 8.9489292 | F40: =(A40-Parametri!$A$11)+Parametri!$A$2+(Parametri!$A$5/2) -> 275.5 | G40: =(D40-Parametri!$A$8)-(A40-Parametri!$A$11)+Parametri!$A$2 -> 767.38704 | H40: =E40 -> 8.9489292 | I40: =Parametri!$D$8 -> 0.11547005 | K40: =C40-B40 -> 31
A41: =A40+2 -> 296 | B41: 1041 | C41: 1064 | D41: =IF(C41=0, B41, GEOMEAN(B41:C41)) -> 1052.4372 | E41: =MAX(Parametri!$D$8, ABS(B41-C41)/(2*SQRT(3))) -> 6.6395281 | F41: =(A41-Parametri!$A$11)+Parametri!$A$2+(Parametri!$A$5/2) -> 277.5 | G41: =(D41-Parametri!$A$8)-(A41-Parametri!$A$11)+Parametri!$A$2 -> 754.43717 | H41: =E41 -> 6.6395281 | I41: =Parametri!$D$8 -> 0.11547005 | K41: =C41-B41 -> 23
A42: =A41+3 -> 299 | B42: 1015 | C42: 1047 | D42: =IF(C42=0, B42, GEOMEAN(B42:C42)) -> 1030.8758 | E42: =MAX(Parametri!$D$8, ABS(B42-C42)/(2*SQRT(3))) -> 9.2376043 | F42: =(A42-Parametri!$A$11)+Parametri!$A$2+(Parametri!$A$5/2) -> 280.5 | G42: =(D42-Parametri!$A$8)-(A42-Parametri!$A$11)+Parametri!$A$2 -> 729.87584 | H42: =E42 -> 9.2376043 | I42: =Parametri!$D$8 -> 0.11547005 | K42: =C42-B42 -> 32
A43: =A42+1 -> 300 | B43: 1011 | C43: 1044 | D43: =IF(C43=0, B43, GEOMEAN(B43:C43)) -> 1027.3675 | E43: =MAX(Parametri!$D$8, ABS(B43-C43)/(2*SQRT(3))) -> 9.5262794 | F43: =(A43-Parametri!$A$11)+Parametri!$A$2+(Parametri!$A$5/2) -> 281.5 | G43: =(D43-Parametri!$A$8)-(A43-Parametri!$A$11)+Parametri!$A$2 -> 725.36751 | H43: =E43 -> 9.5262794 | I43: =Parametri!$D$8 -> 0.11547005 | K43: =C43-B43 -> 33
A44: =A43+1 -> 301 | B44: 1005 | C44: 1037 | D44: =IF(C44=0, B44, GEOMEAN(B44:C44)) -> 1020.8746 | E44: =MAX(Parametri!$D$8, ABS(B44-C44)/(2*SQRT(3))) -> 9.2376043 | F44: =(A44-Parametri!$A$11)+Parametri!$A$2+(Parametri!$A$5/2) -> 282.5 | G44: =(D44-Parametri!$A$8)-(A44-Parametri!$A$11)+Parametri!$A$2 -> 717.87463 | H44: =E44 -> 9.2376043 | I44: =Parametri!$D$8 -> 0.11547005 | K44: =C44-B44 -> 32
A45: =A44+1 -> 302 | B45: 1001 | C45: 1020 | D45: =IF(C45=0, B45, GEOMEAN(B45:C45)) -> 1010.4553 | E45: =MAX(Parametri!$D$8, ABS(B45-C45)/(2*SQRT(3))) -> 5.4848276 | F45: =(A45-Parametri!$A$11)+Parametri!$A$2+(Parametri!$A$5/2) -> 283.5 | G45: =(D45-Parametri!$A$8)-(A45-Parametri!$A$11)+Parametri!$A$2 -> 706.45534 | H45: =E45 -> 5.4848276 | I45: =Parametri!$D$8 -> 0.11547005 | K45: =C45-B45 -> 19
A46: =A45+1 -> 303 | B46: 992 | C46: 1015 | D46: =IF(C46=0, B46, GEOMEAN(B46:C46)) -> 1003.4341 | E46: =MAX(Parametri!$D$8, ABS(B46-C46)/(2*SQRT(3))) -> 6.6395281 | F46: =(A46-Parametri!$A$11)+Parametri!$A$2+(Parametri!$A$5/2) -> 284.5 | G46: =(D46-Parametri!$A$8)-(A46-Parametri!$A$11)+Parametri!$A$2 -> 698.4341 | H46: =E46 -> 6.6395281 | I46: =Parametri!$D$8 -> 0.11547005 | K46: =C46-B46 -> 23 | L46: elimina
A47: =A46+1 -> 304 | B47: 992 | C47: 1015 | D47: =IF(C47=0, B47, GEOMEAN(B47:C47)) -> 1003.4341 | E47: =MAX(Parametri!$D$8, ABS(B47-C47)/(2*SQRT(3))) -> 6.6395281 | F47: =(A47-Parametri!$A$11)+Parametri!$A$2+(Parametri!$A$5/2) -> 285.5 | G47: =(D47-Parametri!$A$8)-(A47-Parametri!$A$11)+Parametri!$A$2 -> 697.4341 | H47: =E47 -> 6.6395281 | I47: =Parametri!$D$8 -> 0.11547005 | K47: =C47-B47 -> 23
A48: =A47+1 -> 305 | B48: 986 | C48: 1006 | D48: =IF(C48=0, B48, GEOMEAN(B48:C48)) -> 995.9498 | E48: =MAX(Parametri!$D$8, ABS(B48-C48)/(2*SQRT(3))) -> 5.7735027 | F48: =(A48-Parametri!$A$11)+Parametri!$A$2+(Parametri!$A$5/2) -> 286.5 | G48: =(D48-Parametri!$A$8)-(A48-Parametri!$A$11)+Parametri!$A$2 -> 688.9498 | H48: =E48 -> 5.7735027 | I48: =Parametri!$D$8 -> 0.11547005 | K48: =C48-B48 -> 20
A49: =A48+1 -> 306 | B49: 985 | C49: 1000 | D49: =IF(C49=0, B49, GEOMEAN(B49:C49)) -> 992.47166 | E49: =MAX(Parametri!$D$8, ABS(B49-C49)/(2*SQRT(3))) -> 4.330127 | F49: =(A49-Parametri!$A$11)+Parametri!$A$2+(Parametri!$A$5/2) -> 287.5 | G49: =(D49-Parametri!$A$8)-(A49-Parametri!$A$11)+Parametri!$A$2 -> 684.47166 | H49: =E49 -> 4.330127 | I49: =Parametri!$D$8 -> 0.11547005 | K49: =C49-B49 -> 15
A50: =A49+1 -> 307 | B50: 981 | C50: 999 | D50: =IF(C50=0, B50, GEOMEAN(B50:C50)) -> 989.95909 | E50: =MAX(Parametri!$D$8, ABS(B50-C50)/(2*SQRT(3))) -> 5.1961524 | F50: =(A50-Parametri!$A$11)+Parametri!$A$2+(Parametri!$A$5/2) -> 288.5 | G50: =(D50-Parametri!$A$8)-(A50-Parametri!$A$11)+Parametri!$A$2 -> 680.95909 | H50: =E50 -> 5.1961524 | I50: =Parametri!$D$8 -> 0.11547005 | K50: =C50-B50 -> 18
A51: =A50+1 -> 308 | B51: 975 | C51: 992 | D51: =IF(C51=0, B51, GEOMEAN(B51:C51)) -> 983.46327 | E51: =MAX(Parametri!$D$8, ABS(B51-C51)/(2*SQRT(3))) -> 4.9074773 | F51: =(A51-Parametri!$A$11)+Parametri!$A$2+(Parametri!$A$5/2) -> 289.5 | G51: =(D51-Parametri!$A$8)-(A51-Parametri!$A$11)+Parametri!$A$2 -> 673.46327 | H51: =E51 -> 4.9074773 | I51: =Parametri!$D$8 -> 0.11547005 | K51: =C51-B51 -> 17
A52: =A51+1 -> 309 | B52: 971 | C52: 988 | D52: =IF(C52=0, B52, GEOMEAN(B52:C52)) -> 979.46312 | E52: =MAX(Parametri!$D$8, ABS(B52-C52)/(2*SQRT(3))) -> 4.9074773 | F52: =(A52-Parametri!$A$11)+Parametri!$A$2+(Parametri!$A$5/2) -> 290.5 | G52: =(D52-Parametri!$A$8)-(A52-Parametri!$A$11)+Parametri!$A$2 -> 668.46312 | H52: =E52 -> 4.9074773 | I52: =Parametri!$D$8 -> 0.11547005 | K52: =C52-B52 -> 17
A53: =A52+1 -> 310 | B53: 968 | C53: 987 | D53: =IF(C53=0, B53, GEOMEAN(B53:C53)) -> 977.45384 | E53: =MAX(Parametri!$D$8, ABS(B53-C53)/(2*SQRT(3))) -> 5.4848276 | F53: =(A53-Parametri!$A$11)+Parametri!$A$2+(Parametri!$A$5/2) -> 291.5 | G53: =(D53-Parametri!$A$8)-(A53-Parametri!$A$11)+Parametri!$A$2 -> 665.45384 | H53: =E53 -> 5.4848276 | I53: =Parametri!$D$8 -> 0.11547005 | K53: =C53-B53 -> 19
A54: =A53+1 -> 311 | B54: 965 | C54: 974 | D54: =IF(C54=0, B54, GEOMEAN(B54:C54)) -> 969.48956 | E54: =MAX(Parametri!$D$8, ABS(B54-C54)/(2*SQRT(3))) -> 2.5980762 | F54: =(A54-Parametri!$A$11)+Parametri!$A$2+(Parametri!$A$5/2) -> 292.5 | G54: =(D54-Parametri!$A$8)-(A54-Parametri!$A$11)+Parametri!$A$2 -> 656.48956 | H54: =E54 -> 2.5980762 | I54: =Parametri!$D$8 -> 0.11547005 | K54: =C54-B54 -> 9
A55: =A54+1 -> 312 | B55: 960 | C55: 976 | D55: =IF(C55=0, B55, GEOMEAN(B55:C55)) -> 967.96694 | E55: =MAX(Parametri!$D$8, ABS(B55-C55)/(2*SQRT(3))) -> 4.6188022 | F55: =(A55-Parametri!$A$11)+Parametri!$A$2+(Parametri!$A$5/2) -> 293.5 | G55: =(D55-Parametri!$A$8)-(A55-Parametri!$A$11)+Parametri!$A$2 -> 653.96694 | H55: =E55 -> 4.6188022 | I55: =Parametri!$D$8 -> 0.11547005 | K55: =C55-B55 -> 16
A56: =A55+1 -> 313 | B56: 957 | C56: 969 | D56: =IF(C56=0, B56, GEOMEAN(B56:C56)) -> 962.98131 | E56: =MAX(Parametri!$D$8, ABS(B56-C56)/(2*SQRT(3))) -> 3.4641016 | F56: =(A56-Parametri!$A$11)+Parametri!$A$2+(Parametri!$A$5/2) -> 294.5 | G56: =(D56-Parametri!$A$8)-(A56-Parametri!$A$11)+Parametri!$A$2 -> 647.98131 | H56: =E56 -> 3.4641016 | I56: =Parametri!$D$8 -> 0.11547005 | K56: =C56-B56 -> 12
A57: =A56+1 -> 314 | B57: 955 | C57: 967 | D57: =IF(C57=0, B57, GEOMEAN(B57:C57)) -> 960.98127 | E57: =MAX(Parametri!$D$8, ABS(B57-C57)/(2*SQRT(3))) -> 3.4641016 | F57: =(A57-Parametri!$A$11)+Parametri!$A$2+(Parametri!$A$5/2) -> 295.5 | G57: =(D57-Parametri!$A$8)-(A57-Parametri!$A$11)+Parametri!$A$2 -> 644.98127 | H57: =E57 -> 3.4641016 | I57: =Parametri!$D$8 -> 0.11547005 | K57: =C57-B57 -> 12
A58: =A57+2 -> 316 | B58: 945 | C58: 961 | D58: =IF(C58=0, B58, GEOMEAN(B58:C58)) -> 952.96642 | E58: =MAX(Parametri!$D$8, ABS(B58-C58)/(2*SQRT(3))) -> 4.6188022 | F58: =(A58-Parametri!$A$11)+Parametri!$A$2+(Parametri!$A$5/2) -> 297.5 | G58: =(D58-Parametri!$A$8)-(A58-Parametri!$A$11)+Parametri!$A$2 -> 634.96642 | H58: =E58 -> 4.6188022 | I58: =Parametri!$D$8 -> 0.11547005 | K58: =C58-B58 -> 16
A59: =A58+2 -> 318 | B59: 940 | C59: 953 | D59: =IF(C59=0, B59, GEOMEAN(B59:C59)) -> 946.47768 | E59: =MAX(Parametri!$D$8, ABS(B59-C59)/(2*SQRT(3))) -> 3.7527767 | F59: =(A59-Parametri!$A$11)+Parametri!$A$2+(Parametri!$A$5/2) -> 299.5 | G59: =(D59-Parametri!$A$8)-(A59-Parametri!$A$11)+Parametri!$A$2 -> 626.47768 | H59: =E59 -> 3.7527767 | I59: =Parametri!$D$8 -> 0.11547005 | K59: =C59-B59 -> 13
...

Sheet Dati (2)
A1: x | B1: y_min | C1: y_max | D1: y_max2 | E1: y | F1: sigma_y | G1: p | H1: q | I1: sigma_p | J1: sigma_q
A2: 270 | D2: =B2+2*E2 -> 3950 | E2: 1975 | F2: =IF(C2=0, Parametri!$D$8, ABS(B2-C2)/(2*SQRT(3))) -> 0.11547005 | G2: =(A2-335)+135.8+(Parametri!$A$5/2) -> 79.3 | H2: =(E2-192)-('Dati (2)'!A2-Parametri!$A$11)+Parametri!$A$2 -> 1748 | I2: =F2 -> 0.11547005 | J2: =Parametri!$D$8 -> 0.11547005
A3: =A2+1 -> 271 | D3: =B3+2*E3 -> 3950 | E3: 1975 | F3: =IF(C3=0, Parametri!$D$8, ABS(B3-C3)/(2*SQRT(3))) -> 0.11547005 | G3: =(A3-335)+135.8+(Parametri!$A$5/2) -> 80.3 | H3: =(E3-192)-('Dati (2)'!A3-Parametri!$A$11)+Parametri!$A$2 -> 1747 | I3: =F3 -> 0.11547005 | J3: =Parametri!$D$8 -> 0.11547005
A4: =A3+1 -> 272 | D4: =B4+2*E4 -> 3824 | E4: 1912 | F4: =IF(C4=0, Parametri!$D$8, ABS(B4-C4)/(2*SQRT(3))) -> 0.11547005 | G4: =(A4-335)+135.8+(Parametri!$A$5/2) -> 81.3 | H4: =(E4-192)-('Dati (2)'!A4-Parametri!$A$11)+Parametri!$A$2 -> 1683 | I4: =F4 -> 0.11547005 | J4: =Parametri!$D$8 -> 0.11547005
A5: =A4+1 -> 273 | D5: =B5+2*E5 -> 3786 | E5: 1893 | F5: =IF(C5=0, Parametri!$D$8, ABS(B5-C5)/(2*SQRT(3))) -> 0.11547005 | G5: =(A5-335)+135.8+(Parametri!$A$5/2) -> 82.3 | H5: =(E5-192)-('Dati (2)'!A5-Parametri!$A$11)+Parametri!$A$2 -> 1663 | I5: =F5 -> 0.11547005 | J5: =Parametri!$D$8 -> 0.11547005
A6: =A5+1 -> 274 | D6: =B6+2*E6 -> 3634 | E6: 1817 | F6: =IF(C6=0, Parametri!$D$8, ABS(B6-C6)/(2*SQRT(3))) -> 0.11547005 | G6: =(A6-335)+135.8+(Parametri!$A$5/2) -> 83.3 | H6: =(E6-192)-('Dati (2)'!A6-Parametri!$A$11)+Parametri!$A$2 -> 1586 | I6: =F6 -> 0.11547005 | J6: =Parametri!$D$8 -> 0.11547005
A7: =A6+1 -> 275 | D7: =B7+2*E7 -> 3566 | E7: 1783 | F7: =IF(C7=0, Parametri!$D$8, ABS(B7-C7)/(2*SQRT(3))) -> 0.11547005 | G7: =(A7-335)+135.8+(Parametri!$A$5/2) -> 84.3 | H7: =(E7-192)-('Dati (2)'!A7-Parametri!$A$11)+Parametri!$A$2 -> 1551 | I7: =F7 -> 0.11547005 | J7: =Parametri!$D$8 -> 0.11547005
A8: =A7+1 -> 276 | D8: =B8+2*E8 -> 3447 | E8: 1723.5 | F8: =IF(C8=0, Parametri!$D$8, ABS(B8-C8)/(2*SQRT(3))) -> 0.11547005 | G8: =(A8-335)+135.8+(Parametri!$A$5/2) -> 85.3 | H8: =(E8-192)-('Dati (2)'!A8-Parametri!$A$11)+Parametri!$A$2 -> 1490.5 | I8: =F8 -> 0.11547005 | J8: =Parametri!$D$8 -> 0.11547005
A9: =A8+1 -> 277 | D9: =B9+2*E9 -> 3352 | E9: 1676 | F9: =IF(C9=0, Parametri!$D$8, ABS(B9-C9)/(2*SQRT(3))) -> 0.11547005 | G9: =(A9-335)+135.8+(Parametri!$A$5/2) -> 86.3 | H9: =(E9-192)-('Dati (2)'!A9-Parametri!$A$11)+Parametri!$A$2 -> 1442 | I9: =F9 -> 0.11547005 | J9: =Parametri!$D$8 -> 0.11547005
A10: =A9+1 -> 278 | D10: =B10+2*E10 -> 3320 | E10: 1660 | F10: =IF(C10=0, Parametri!$D$8, ABS(B10-C10)/(2*SQRT(3))) -> 0.11547005 | G10: =(A10-335)+135.8+(Parametri!$A$5/2) -> 87.3 | H10: =(E10-192)-('Dati (2)'!A10-Parametri!$A$11)+Parametri!$A$2 -> 1425 | I10: =F10 -> 0.11547005 | J10: =Parametri!$D$8 -> 0.11547005
A11: =A10+1 -> 279 | D11: =B11+2*E11 -> 3231 | E11: 1615.5 | F11: =IF(C11=0, Parametri!$D$8, ABS(B11-C11)/(2*SQRT(3))) -> 0.11547005 | G11: =(A11-335)+135.8+(Parametri!$A$5/2) -> 88.3 | H11: =(E11-192)-('Dati (2)'!A11-Parametri!$A$11)+Parametri!$A$2 -> 1379.5 | I11: =F11 -> 0.11547005 | J11: =Parametri!$D$8 -> 0.11547005
A12: =A11+1 -> 280 | D12: =B12+2*E12 -> 3163 | E12: 1581.5 | F12: =IF(C12=0, Parametri!$D$8, ABS(B12-C12)/(2*SQRT(3))) -> 0.11547005 | G12: =(A12-335)+135.8+(Parametri!$A$5/2) -> 89.3 | H12: =(E12-192)-('Dati (2)'!A12-Parametri!$A$11)+Parametri!$A$2 -> 1344.5 | I12: =F12 -> 0.11547005 | J12: =Parametri!$D$8 -> 0.11547005
A13: =A12+1 -> 281 | D13: =B13+2*E13 -> 3122 | E13: 1561 | F13: =IF(C13=0, Parametri!$D$8, ABS(B13-C13)/(2*SQRT(3))) -> 0.11547005 | G13: =(A13-335)+135.8+(Parametri!$A$5/2) -> 90.3 | H13: =(E13-192)-('Dati (2)'!A13-Parametri!$A$11)+Parametri!$A$2 -> 1323 | I13: =F13 -> 0.11547005 | J13: =Parametri!$D$8 -> 0.11547005
A14: =A13+1 -> 282 | D14: =B14+2*E14 -> 3067 | E14: 1533.5 | F14: =IF(C14=0, Parametri!$D$8, ABS(B14-C14)/(2*SQRT(3))) -> 0.11547005 | G14: =(A14-335)+135.8+(Parametri!$A$5/2) -> 91.3 | H14: =(E14-192)-('Dati (2)'!A14-Parametri!$A$11)+Parametri!$A$2 -> 1294.5 | I14: =F14 -> 0.11547005 | J14: =Parametri!$D$8 -> 0.11547005
... A47: =A46+1 -> 315 | D47: =B47+2*E47 -> 2150 | E47: 1075 | F47: =IF(C47=0, Parametri!$D$8, ABS(B47-C47)/(2*SQRT(3))) -> 0.11547005 | G47: =(A47-335)+135.8+(Parametri!$A$5/2) -> 124.3 | H47: =(E47-192)-('Dati (2)'!A47-Parametri!$A$11)+Parametri!$A$2 -> 803 | I47: =F47 -> 0.11547005 | J47: =Parametri!$D$8 -> 0.11547005
A48: =A47+2 -> 317 | D48: =B48+2*E48 -> 2126 | E48: 1063 | F48: =IF(C48=0, Parametri!$D$8, ABS(B48-C48)/(2*SQRT(3))) -> 0.11547005 | G48: =(A48-335)+135.8+(Parametri!$A$5/2) -> 126.3 | H48: =(E48-192)-('Dati (2)'!A48-Parametri!$A$11)+Parametri!$A$2 -> 789 | I48: =F48 -> 0.11547005 | J48: =Parametri!$D$8 -> 0.11547005
A49: =A48+2 -> 319 | D49: =B49+2*E49 -> 2085 | E49: 1042.5 | F49: =IF(C49=0, Parametri!$D$8, ABS(B49-C49)/(2*SQRT(3))) -> 0.11547005 | G49: =(A49-335)+135.8+(Parametri!$A$5/2) -> 128.3 | H49: =(E49-192)-('Dati (2)'!A49-Parametri!$A$11)+Parametri!$A$2 -> 766.5 | I49: =F49 -> 0.11547005 | J49: =Parametri!$D$8 -> 0.11547005
A50: =A49+2 -> 321 | D50: =B50+2*E50 -> 2068 | E50: 1034 | F50: =IF(C50=0, Parametri!$D$8, ABS(B50-C50)/(2*SQRT(3))) -> 0.11547005 | G50: =(A50-335)+135.8+(Parametri!$A$5/2) -> 130.3 | H50: =(E50-192)-('Dati (2)'!A50-Parametri!$A$11)+Parametri!$A$2 -> 756 | I50: =F50 -> 0.11547005 | J50: =Parametri!$D$8 -> 0.11547005
A51: =A50+2 -> 323 | D51: =B51+2*E51 -> 2055 | E51: 1027.5 | F51: =IF(C51=0, Parametri!$D$8, ABS(B51-C51)/(2*SQRT(3))) -> 0.11547005 | G51: =(A51-335)+135.8+(Parametri!$A$5/2) -> 132.3 | H51: =(E51-192)-('Dati (2)'!A51-Parametri!$A$11)+Parametri!$A$2 -> 747.5 | I51: =F51 -> 0.11547005 | J51: =Parametri!$D$8 -> 0.11547005
A52: =A51+2 -> 325 | D52: =B52+2*E52 -> 2020 | E52: 1010 | F52: =IF(C52=0, Parametri!$D$8, ABS(B52-C52)/(2*SQRT(3))) -> 0.11547005 | G52: =(A52-335)+135.8+(Parametri!$A$5/2) -> 134.3 | H52: =(E52-192)-('Dati (2)'!A52-Parametri!$A$11)+Parametri!$A$2 -> 728 | I52: =F52 -> 0.11547005 | J52: =Parametri!$D$8 -> 0.11547005
A53: =A52+2 -> 327 | D53: =B53+2*E53 -> 1999 | E53: 999.5 | F53: =IF(C53=0, Parametri!$D$8, ABS(B53-C53)/(2*SQRT(3))) -> 0.11547005 | G53: =(A53-335)+135.8+(Parametri!$A$5/2) -> 136.3 | H53: =(E53-192)-('Dati (2)'!A53-Parametri!$A$11)+Parametri!$A$2 -> 715.5 | I53: =F53 -> 0.11547005 | J53: =Parametri!$D$8 -> 0.11547005
A54: =A53+2 -> 329 | D54: =B54+2*E54 -> 1975 | E54: 987.5 | F54: =IF(C54=0, Parametri!$D$8, ABS(B54-C54)/(2*SQRT(3))) -> 0.11547005 | G54: =(A54-335)+135.8+(Parametri!$A$5/2) -> 138.3 | H54: =(E54-192)-('Dati (2)'!A54-Parametri!$A$11)+Parametri!$A$2 -> 701.5 | I54: =F54 -> 0.11547005 | J54: =Parametri!$D$8 -> 0.11547005
A55: =A54+2 -> 331 | D55: =B55+2*E55 -> 1961 | E55: 980.5 | F55: =IF(C55=0, Parametri!$D$8, ABS(B55-C55)/(2*SQRT(3))) -> 0.11547005 | G55: =(A55-335)+135.8+(Parametri!$A$5/2) -> 140.3 | H55: =(E55-192)-('Dati (2)'!A55-Parametri!$A$11)+Parametri!$A$2 -> 692.5 | I55: =F55 -> 0.11547005 | J55: =Parametri!$D$8 -> 0.11547005
A56: =A55+2 -> 333 | D56: =B56+2*E56 -> 1940 | E56: 970 | F56: =IF(C56=0, Parametri!$D$8, ABS(B56-C56)/(2*SQRT(3))) -> 0.11547005 | G56: =(A56-335)+135.8+(Parametri!$A$5/2) -> 142.3 | H56: =(E56-192)-('Dati (2)'!A56-Parametri!$A$11)+Parametri!$A$2 -> 680 | I56: =F56 -> 0.11547005 | J56: =Parametri!$D$8 -> 0.11547005
A57: =A56+2 -> 335 | D57: =B57+2*E57 -> 1910 | E57: 955 | F57: =IF(C57=0, Parametri!$D$8, ABS(B57-C57)/(2*SQRT(3))) -> 0.11547005 | G57: =(A57-335)+135.8+(Parametri!$A$5/2) -> 144.3 | H57: =(E57-192)-('Dati (2)'!A57-Parametri!$A$11)+Parametri!$A$2 -> 663 | I57: =F57 -> 0.11547005 | J57: =Parametri!$D$8 -> 0.11547005
A58: =A57+2 -> 337 | D58: =B58+2*E58 -> 1891 | E58: 945.5 | F58: =IF(C58=0, Parametri!$D$8, ABS(B58-C58)/(2*SQRT(3))) -> 0.11547005 | G58: =(A58-335)+135.8+(Parametri!$A$5/2) -> 146.3 | H58: =(E58-192)-('Dati (2)'!A58-Parametri!$A$11)+Parametri!$A$2 -> 651.5 | I58: =F58 -> 0.11547005 | J58: =Parametri!$D$8 -> 0.11547005
A59: =A58+2 -> 339 | D59: =B59+2*E59 -> 1887 | E59: 943.5 | F59: =IF(C59=0, Parametri!$D$8, ABS(B59-C59)/(2*SQRT(3))) -> 0.11547005 | G59: =(A59-335)+135.8+(Parametri!$A$5/2) -> 148.3 | H59: =(E59-192)-('Dati (2)'!A59-Parametri!$A$11)+Parametri!$A$2 -> 647.5 | I59: =F59 -> 0.11547005 | J59: =Parametri!$D$8 -> 0.11547005
... A65: =A64+2 -> 351 | D65: =B65+2*E65 -> 1812 | E65: 906 | F65: =IF(C65=0, Parametri!$D$8, ABS(B65-C65)/(2*SQRT(3))) -> 0.11547005 | G65: =(A65-335)+135.8+(Parametri!$A$5/2) -> 160.3 | H65: =(E65-192)-('Dati (2)'!A65-Parametri!$A$11)+Parametri!$A$2 -> 598 | I65: =F65 -> 0.11547005 | J65: =Parametri!$D$8 -> 0.11547005
A66: =A65+3 -> 354 | D66: =B66+2*E66 -> 1806 | E66: 903 | F66: =IF(C66=0, Parametri!$D$8, ABS(B66-C66)/(2*SQRT(3))) -> 0.11547005 | G66: =(A66-335)+135.8+(Parametri!$A$5/2) -> 163.3 | H66: =(E66-192)-('Dati (2)'!A66-Parametri!$A$11)+Parametri!$A$2 -> 592 | I66: =F66 -> 0.11547005 | J66: =Parametri!$D$8 -> 0.11547005
A67: =A66+3 -> 357 | D67: =B67+2*E67 -> 1782 | E67: 891 | F67: =IF(C67=0, Parametri!$D$8, ABS(B67-C67)/(2*SQRT(3))) -> 0.11547005 | G67: =(A67-335)+135.8+(Parametri!$A$5/2) -> 166.3 | H67: =(E67-192)-('Dati (2)'!A67-Parametri!$A$11)+Parametri!$A$2 -> 577 | I67: =F67 -> 0.11547005 | J67: =Parametri!$D$8 -> 0.11547005
A68: =A67+3 -> 360 | D68: =B68+2*E68 -> 1777 | E68: 888.5 | F68: =IF(C68=0, Parametri!$D$8, ABS(B68-C68)/(2*SQRT(3))) -> 0.11547005 | G68: =(A68-335)+135.8+(Parametri!$A$5/2) -> 169.3 | H68: =(E68-192)-('Dati (2)'!A68-Parametri!$A$11)+Parametri!$A$2 -> 571.5 | I68: =F68 -> 0.11547005 | J68: =Parametri!$D$8 -> 0.11547005
A69: =A68+3 -> 363 | D69: =B69+2*E69 -> 1780 | E69: 890 | F69: =IF(C69=0, Parametri!$D$8, ABS(B69-C69)/(2*SQRT(3))) -> 0.11547005 | G69: =(A69-335)+135.8+(Parametri!$A$5/2) -> 172.3 | H69: =(E69-192)-('Dati (2)'!A69-Parametri!$A$11)+Parametri!$A$2 -> 570 | I69: =F69 -> 0.11547005 | J69: =Parametri!$D$8 -> 0.11547005
A70: =A69+3 -> 366 | D70: =B70+2*E70 -> 1752 | E70: 876 | F70: =IF(C70=0, Parametri!$D$8, ABS(B70-C70)/(2*SQRT(3))) -> 0.11547005 | G70: =(A70-335)+135.8+(Parametri!$A$5/2) -> 175.3 | H70: =(E70-192)-('Dati (2)'!A70-Parametri!$A$11)+Parametri!$A$2 -> 553 | I70: =F70 -> 0.11547005 | J70: =Parametri!$D$8 -> 0.11547005
A71: =A70+3 -> 369 | D71: =B71+2*E71 -> 1744 | E71: 872 | F71: =IF(C71=0, Parametri!$D$8, ABS(B71-C71)/(2*SQRT(3))) -> 0.11547005 | G71: =(A71-335)+135.8+(Parametri!$A$5/2) -> 178.3 | H71: =(E71-192)-('Dati (2)'!A71-Parametri!$A$11)+Parametri!$A$2 -> 546 | I71: =F71 -> 0.11547005 | J71: =Parametri!$D$8 -> 0.11547005
A72: =A71+3 -> 372 | D72: =B72+2*E72 -> 1742 | E72: 871 | F72: =IF(C72=0, Parametri!$D$8, ABS(B72-C72)/(2*SQRT(3))) -> 0.11547005 | G72: =(A72-335)+135.8+(Parametri!$A$5/2) -> 181.3 | H72: =(E72-192)-('Dati (2)'!A72-Parametri!$A$11)+Parametri!$A$2 -> 542 | I72: =F72 -> 0.11547005 | J72: =Parametri!$D$8 -> 0.11547005
A73: =A72+3 -> 375 | D73: =B73+2*E73 -> 1734 | E73: 867 | F73: =IF(C73=0, Parametri!$D$8, ABS(B73-C73)/(2*SQRT(3))) -> 0.11547005 | G73: =(A73-335)+135.8+(Parametri!$A$5/2) -> 184.3 | H73: =(E73-192)-('Dati (2)'!A73-Parametri!$A$11)+Parametri!$A$2 -> 535 | I73: =F73 -> 0.11547005 | J73: =Parametri!$D$8 -> 0.11547005
A74: =A73+4 -> 379 | D74: =B74+2*E74 -> 1721 | E74: 860.5 | F74: =IF(C74=0, Parametri!$D$8, ABS(B74-C74)/(2*SQRT(3))) -> 0.11547005 | G74: =(A74-335)+135.8+(Parametri!$A$5/2) -> 188.3 | H74: =(E74-192)-('Dati (2)'!A74-Parametri!$A$11)+Parametri!$A$2 -> 524.5 | I74: =F74 -> 0.11547005 | J74: =Parametri!$D$8 -> 0.11547005
A75: =A74+4 -> 383 | D75: =B75+2*E75 -> 1720 | E75: 860 | F75: =IF(C75=0, Parametri!$D$8, ABS(B75-C75)/(2*SQRT(3))) -> 0.11547005 | G75: =(A75-335)+135.8+(Parametri!$A$5/2) -> 192.3 | H75: =(E75-192)-('Dati (2)'!A75-Parametri!$A$11)+Parametri!$A$2 -> 520 | I75: =F75 -> 0.11547005 | J75: =Parametri!$D$8 -> 0.11547005
A76: =A75+4 -> 387 | D76: =B76+2*E76 -> 1706 | E76: 853 | F76: =IF(C76=0, Parametri!$D$8, ABS(B76-C76)/(2*SQRT(3))) -> 0.11547005 | G76: =(A76-335)+135.8+(Parametri!$A$5/2) -> 196.3 | H76: =(E76-192)-('Dati (2)'!A76-Parametri!$A$11)+Parametri!$A$2 -> 509 | I76: =F76 -> 0.11547005 | J76: =Parametri!$D$8 -> 0.11547005
A77: =A76+4 -> 391 | D77: =B77+2*E77 -> 1695 | E77: 847.5 | F77: =IF(C77=0, Parametri!$D$8, ABS(B77-C77)/(2*SQRT(3))) -> 0.11547005 | G77: =(A77-335)+135.8+(Parametri!$A$5/2) -> 200.3 | H77: =(E77-192)-('Dati (2)'!A77-Parametri!$A$11)+Parametri!$A$2 -> 499.5 | I77: =F77 -> 0.11547005 | J77: =Parametri!$D$8 -> 0.11547005
...
