Workbook

Sheet Parametri
A1: L | B1: err_L | C1: sigma_L
A2: 104 | B2: =1/20 | C2: =B5/SQRT(3)
A4: D | B4: err_D | C4: sigma_D
A5: 17 | B5: =1/20 | C5: =B5/SQRT(3)
A7: y_0 | B7: err_y0 | C7: sigma_y0 | D7: sigma_y
A8: 237 | B8: 0.2 | C8: =B8/SQRT(3) | D8: =B8/SQRT(3)
A10: x_0 | B10: err_x0 | C10: sigma_x0 | D10: sigma_x
A11: 131 | B11: 0.2 | C11: =B11/SQRT(3) | D11: =B11/SQRT(3)

Sheet Datisium
A1: x | B1: y_min | C1: y_max | D1: y | E1: sigma_y | F1: p | G1: q | H1: sigma_p | I1: sigma_q
A2: 251 | B2: 1802 | C2: 1841 | D2: =IF(C2=0, B2, GEOMEAN(B2:C2)) | E2: =MAX(Parametri!$D$8, ABS(B2-C2)/(2*SQRT(3))) | F2: =(A2-Parametri!$A$11)+Parametri!$A$2+(Parametri!$A$5/2) | G2: =(D2-Parametri!$A$8)-(A2-Parametri!$A$11)+Parametri!$A$2 | H2: =E2 | I2: =Parametri!$D$8 | K2: =C2-B2 | L2: FONTE DI ERRORE | U2: 0 | V2: 0
A3: =A2+1 | B3: 1719 | C3: 1836 | D3: =IF(C3=0, B3, GEOMEAN(B3:C3)) | E3: =MAX(Parametri!$D$8, ABS(B3-C3)/(2*SQRT(3))) | F3: =(A3-Parametri!$A$11)+Parametri!$A$2+(Parametri!$A$5/2) | G3: =(D3-Parametri!$A$8)-(A3-Parametri!$A$11)+Parametri!$A$2 | H3: =E3 | I3: =Parametri!$D$8 | K3: =C3-B3 | L3: modifica messa a fuoco fonte di errore dovuta al generatore | U3: 2000 | V3: 2000
A4: =A3+1 | B4: 1690 | C4: 1853 | D4: =IF(C4=0, B4, GEOMEAN(B4:C4)) | E4: =MAX(Parametri!$D$8, ABS(B4-C4)/(2*SQRT(3))) | F4: =(A4-Parametri!$A$11)+Parametri!$A$2+(Parametri!$A$5/2) | G4: =(D4-Parametri!$A$8)-(A4-Parametri!$A$11)+Parametri!$A$2 | H4: =E4 | I4: =Parametri!$D$8 | K4: =C4-B4
A5: =A4+1 | B5: 1630 | C5: 1782 | D5: =IF(C5=0, B5, GEOMEAN(B5:C5)) | E5: =MAX(Parametri!$D$8, ABS(B5-C5)/(2*SQRT(3))) | F5: =(A5-Parametri!$A$11)+Parametri!$A$2+(Parametri!$A$5/2) | G5: =(D5-Parametri!$A$8)-(A5-Parametri!$A$11)+Parametri!$A$2 | H5: =E5 | I5: =Parametri!$D$8 | K5: =C5-B5
A6: =A5+1 | B6: 1605 | C6: 1745 | D6: =IF(C6=0, B6, GEOMEAN(B6:C6)) | E6: =MAX(Parametri!$D$8, ABS(B6-C6)/(2*SQRT(3))) | F6: =(A6-Parametri!$A$11)+Parametri!$A$2+(Parametri!$A$5/2) | G6: =(D6-Parametri!$A$8)-(A6-Parametri!$A$11)+Parametri!$A$2 | H6: =E6 | I6: =Parametri!$D$8 | K6: =C6-B6
A7: =A6+1 | B7: 1574 | C7: 1710 | D7: =IF(C7=0, B7, GEOMEAN(B7:C7)) | E7: =MAX(Parametri!$D$8, ABS(B7-C7)/(2*SQRT(3))) | F7: =(A7-Parametri!$A$11)+Parametri!$A$2+(Parametri!$A$5/2) | G7: =(D7-Parametri!$A$8)-(A7-Parametri!$A$11)+Parametri!$A$2 | H7: =E7 | I7: =Parametri!$D$8 | K7: =C7-B7
A8: =A7+1 | B8: 1546 | C8: 1679 | D8: =IF(C8=0, B8, GEOMEAN(B8:C8)) | E8: =MAX(Parametri!$D$8, ABS(B8-C8)/(2*SQRT(3))) | F8: =(A8-Parametri!$A$11)+Parametri!$A$2+(Parametri!$A$5/2) | G8: =(D8-Parametri!$A$8)-(A8-Parametri!$A$11)+Parametri!$A$2 | H8: =E8 | I8: =Parametri!$D$8 | K8: =C8-B8
A9: =A8+1 | B9: 1525 | C9: 1629 | D9: =IF(C9=0, B9, GEOMEAN(B9:C9)) | E9: =MAX(Parametri!$D$8, ABS(B9-C9)/(2*SQRT(3))) | F9: =(A9-Parametri!$A$11)+Parametri!$A$2+(Parametri!$A$5/2) | G9: =(D9-Parametri!$A$8)-(A9-Parametri!$A$11)+Parametri!$A$2 | H9: =E9 | I9: =Parametri!$D$8 | K9: =C9-B9
A10: =A9+1 | B10: 1505 | C10: 1603 | D10: =IF(C10=0, B10, GEOMEAN(B10:C10)) | E10: =MAX(Parametri!$D$8, ABS(B10-C10)/(2*SQRT(3))) | F10: =(A10-Parametri!$A$11)+Parametri!$A$2+(Parametri!$A$5/2) | G10: =(D10-Parametri!$A$8)-(A10-Parametri!$A$11)+Parametri!$A$2 | H10: =E10 | I10: =Parametri!$D$8 | K10: =C10-B10
A11: =A10+1 | B11: 1467 | C11: 1572 | D11: =IF(C11=0, B11, GEOMEAN(B11:C11)) | E11: =MAX(Parametri!$D$8, ABS(B11-C11)/(2*SQRT(3))) | F11: =(A11-Parametri!$A$11)+Parametri!$A$2+(Parametri!$A$5/2) | G11: =(D11-Parametri!$A$8)-(A11-Parametri!$A$11)+Parametri!$A$2 | H11: =E11 | I11: =Parametri!$D$8 | K11: =C11-B11
A12: =A11+1 | B12: 1452 | C12: 1534 | D12: =IF(C12=0, B12, GEOMEAN(B12:C12)) | E12: =MAX(Parametri!$D$8, ABS(B12-C12)/(2*SQRT(3))) | F12: =(A12-Parametri!$A$11)+Parametri!$A$2+(Parametri!$A$5/2) | G12: =(D12-Parametri!$A$8)-(A12-Parametri!$A$11)+Parametri!$A$2 | H12: =E12 | I12: =Parametri!$D$8 | K12: =C12-B12
A13: =A12+1 | B13: 1442 | C13: 1520 | D13: =IF(C13=0, B13, GEOMEAN(B13:C13)) | E13: =MAX(Parametri!$D$8, ABS(B13-C13)/(2*SQRT(3))) | F13: =(A13-Parametri!$A$11)+Parametri!$A$2+(Parametri!$A$5/2) | G13: =(D13-Parametri!$A$8)-(A13-Parametri!$A$11)+Parametri!$A$2 | H13: =E13 | I13: =Parametri!$D$8 | K13: =C13-B13
A14: =A13+1 | B14: 1402 | C14: 1485 | D14: =IF(C14=0, B14, GEOMEAN(B14:C14)) | E14: =MAX(Parametri!$D$8, ABS(B14-C14)/(2*SQRT(3))) | F14: =(A14-Parametri!$A$11)+Parametri!$A$2+(Parametri!$A$5/2) | G14: =(D14-Parametri!$A$8)-(A14-Parametri!$A$11)+Parametri!$A$2 | H14: =E14 | I14: =Parametri!$D$8 | K14: =C14-B14
A15: =A14+1 | B15: 1391 | C15: 1462 | D15: =IF(C15=0, B15, GEOMEAN(B15:C15)) | E15: =MAX(Parametri!$D$8, ABS(B15-C15)/(2*SQRT(3))) | F15: =(A15-Parametri!$A$11)+Parametri!$A$2+(Parametri!$A$5/2) | G15: =(D15-Parametri!$A$8)-(A15-Parametri!$A$11)+Parametri!$A$2 | H15: =E15 | I15: =Parametri!$D$8 | K15: =C15-B15
... A35: =A34+1 | B35: 1122 | C35: 1163 | D35: =IF(C35=0, B35, GEOMEAN(B35:C35)) | E35: =MAX(Parametri!$D$8, ABS(B35-C35)/(2*SQRT(3))) | F35: =(A35-Parametri!$A$11)+Parametri!$A$2+(Parametri!$A$5/2) | G35: =(D35-Parametri!$A$8)-(A35-Parametri!$A$11)+Parametri!$A$2 | H35: =E35 | I35: =Parametri!$D$8 | K35: =C35-B35
A36: =A35+2 | B36: 1110 | C36: 1138 | D36: =IF(C36=0, B36, GEOMEAN(B36:C36)) | E36: =MAX(Parametri!$D$8, ABS(B36-C36)/(2*SQRT(3))) | F36: =(A36-Parametri!$A$11)+Parametri!$A$2+(Parametri!$A$5/2) | G36: =(D36-Parametri!$A$8)-(A36-Parametri!$A$11)+Parametri!$A$2 | H36: =E36 | I36: =Parametri!$D$8 | K36: =C36-B36
A37: =A36+2 | B37: 1094 | C37: 1121 | D37: =IF(C37=0, B37, GEOMEAN(B37:C37)) | E37: =MAX(Parametri!$D$8, ABS(B37-C37)/(2*SQRT(3))) | F37: =(A37-Parametri!$A$11)+Parametri!$A$2+(Parametri!$A$5/2) | G37: =(D37-Parametri!$A$8)-(A37-Parametri!$A$11)+Parametri!$A$2 | H37: =E37 | I37: =Parametri!$D$8 | K37: =C37-B37
A38: =A37+2 | B38: 1076 | C38: 1107 | D38: =IF(C38=0, B38, GEOMEAN(B38:C38)) | E38: =MAX(Parametri!$D$8, ABS(B38-C38)/(2*SQRT(3))) | F38: =(A38-Parametri!$A$11)+Parametri!$A$2+(Parametri!$A$5/2) | G38: =(D38-Parametri!$A$8)-(A38-Parametri!$A$11)+Parametri!$A$2 | H38: =E38 | I38: =Parametri!$D$8 | K38: =C38-B38
A39: =A38+2 | B39: 1064 | C39: 1092 | D39: =IF(C39=0, B39, GEOMEAN(B39:C39)) | E39: =MAX(Parametri!$D$8, ABS(B39-C39)/(2*SQRT(3))) | F39: =(A39-Parametri!$A$11)+Parametri!$A$2+(Parametri!$A$5/2) | G39: =(D39-Parametri!$A$8)-(A39-Parametri!$A$11)+Parametri!$A$2 | H39: =E39 | I39: =Parametri!$D$8 | K39: =C39-B39
A40: =A39+2 | B40: 1048 | C40: 1079 | D40: =IF(C40=0, B40, GEOMEAN(B40:C40)) | E40: =MAX(Parametri!$D$8, ABS(B40-C40)/(2*SQRT(3))) | F40: =(A40-Parametri!$A$11)+Parametri!$A$2+(Parametri!$A$5/2) | G40: =(D40-Parametri!$A$8)-(A40-Parametri!$A$11)+Parametri!$A$2 | H40: =E40 | I40: =Parametri!$D$8 | K40: =C40-B40
A41: =A40+2 | B41: 1041 | C41: 1064 | D41: =IF(C41=0, B41, GEOMEAN(B41:C41)) | E41: =MAX(Parametri!$D$8, ABS(B41-C41)/(2*SQRT(3))) | F41: =(A41-Parametri!$A$11)+Parametri!$A$2+(Parametri!$A$5/2) | G41: =(D41-Parametri!$A$8)-(A41-Parametri!$A$11)+Parametri!$A$2 | H41: =E41 | I41: =Parametri!$D$8 | K41: =C41-B41
A42: =A41+3 | B42: 1015 | C42: 1047 | D42: =IF(C42=0, B42, GEOMEAN(B42:C42)) | E42: =MAX(Parametri!$D$8, ABS(B42-C42)/(2*SQRT(3))) | F42: =(A42-Parametri!$A$11)+Parametri!$A$2+(Parametri!$A$5/2) | G42: =(D42-Parametri!$A$8)-(A42-Parametri!$A$11)+Parametri!$A$2 | H42: =E42 | I42: =Parametri!$D$8 | K42: =C42-B42
A43: =A42+1 | B43: 1011 | C43: 1044 | D43: =IF(C43=0, B43, GEOMEAN(B43:C43)) | E43: =MAX(Parametri!$D$8, ABS(B43-C43)/(2*SQRT(3))) | F43: =(A43-Parametri!$A$11)+Parametri!$A$2+(Parametri!$A$5/2) | G43: =(D43-Parametri!$A$8)-(A43-Parametri!$A$11)+Parametri!$A$2 | H43: =E43 | I43: =Parametri!$D$8 | K43: =C43-B43
A44: =A43+1 | B44: 1005 | C44: 1037 | D44: =IF(C44=0, B44, GEOMEAN(B44:C44)) | E44: =MAX(Parametri!$D$8, ABS(B44-C44)/(2*SQRT(3))) | F44: =(A44-Parametri!$A$11)+Parametri!$A$2+(Parametri!$A$5/2) | G44: =(D44-Parametri!$A$8)-(A44-Parametri!$A$11)+Parametri!$A$2 | H44: =E44 | I44: =Parametri!$D$8 | K44: =C44-B44
A45: =A44+1 | B45: 1001 | C45: 1020 | D45: =IF(C45=0, B45, GEOMEAN(B45:C45)) | E45: =MAX(Parametri!$D$8, ABS(B45-C45)/(2*SQRT(3))) | F45: =(A45-Parametri!$A$11)+Parametri!$A$2+(Parametri!$A$5/2) | G45: =(D45-Parametri!$A$8)-(A45-Parametri!$A$11)+Parametri!$A$2 | H45: =E45 | I45: =Parametri!$D$8 | K45: =C45-B45
A46: =A45+1 | B46: 992 | C46: 1015 | D46: =IF(C46=0, B46, GEOMEAN(B46:C46)) | E46: =MAX(Parametri!$D$8, ABS(B46-C46)/(2*SQRT(3))) | F46: =(A46-Parametri!$A$11)+Parametri!$A$2+(Parametri!$A$5/2) | G46: =(D46-Parametri!$A$8)-(A46-Parametri!$A$11)+Parametri!$A$2 | H46: =E46 | I46: =Parametri!$D$8 | K46: =C46-B46 | L46: elimina
A47: =A46+1 | B47: 992 | C47: 1015 | D47: =IF(C47=0, B47, GEOMEAN(B47:C47)) | E47: =MAX(Parametri!$D$8, ABS(B47-C47)/(2*SQRT(3))) | F47: =(A47-Parametri!$A$11)+Parametri!$A$2+(Parametri!$A$5/2) | G47: =(D47-Parametri!$A$8)-(A47-Parametri!$A$11)+Parametri!$A$2 | H47: =E47 | I47: =Parametri!$D$8 | K47: =C47-B47
A48: =A47+1 | B48: 986 | C48: 1006 | D48: =IF(C48=0, B48, GEOMEAN(B48:C48)) | E48: =MAX(Parametri!$D$8, ABS(B48-C48)/(2*SQRT(3))) | F48: =(A48-Parametri!$A$11)+Parametri!$A$2+(Parametri!$A$5/2) | G48: =(D48-Parametri!$A$8)-(A48-Parametri!$A$11)+Parametri!$A$2 | H48: =E48 | I48: =Parametri!$D$8 | K48: =C48-B48
A49: =A48+1 | B49: 985 | C49: 1000 | D49: =IF(C49=0, B49, GEOMEAN(B49:C49)) | E49: =MAX(Parametri!$D$8, ABS(B49-C49)/(2*SQRT(3))) | F49: =(A49-Parametri!$A$11)+Parametri!$A$2+(Parametri!$A$5/2) | G49: =(D49-Parametri!$A$8)-(A49-Parametri!$A$11)+Parametri!$A$2 | H49: =E49 | I49: =Parametri!$D$8 | K49: =C49-B49
A50: =A49+1 | B50: 981 | C50: 999 | D50: =IF(C50=0, B50, GEOMEAN(B50:C50)) | E50: =MAX(Parametri!$D$8, ABS(B50-C50)/(2*SQRT(3))) | F50: =(A50-Parametri!$A$11)+Parametri!$A$2+(Parametri!$A$5/2) | G50: =(D50-Parametri!$A$8)-(A50-Parametri!$A$11)+Parametri!$A$2 | H50: =E50 | I50: =Parametri!$D$8 | K50: =C50-B50
A51: =A50+1 | B51: 975 | C51: 992 | D51: =IF(C51=0, B51, GEOMEAN(B51:C51)) | E51: =MAX(Parametri!$D$8, ABS(B51-C51)/(2*SQRT(3))) | F51: =(A51-Parametri!$A$11)+Parametri!$A$2+(Parametri!$A$5/2) | G51: =(D51-Parametri!$A$8)-(A51-Parametri!$A$11)+Parametri!$A$2 | H51: =E51 | I51: =Parametri!$D$8 | K51: =C51-B51
A52: =A51+1 | B52: 971 | C52: 988 | D52: =IF(C52=0, B52, GEOMEAN(B52:C52)) | E52: =MAX(Parametri!$D$8, ABS(B52-C52)/(2*SQRT(3))) | F52: =(A52-Parametri!$A$11)+Parametri!$A$2+(Parametri!$A$5/2) | G52: =(D52-Parametri!$A$8)-(A52-Parametri!$A$11)+Parametri!$A$2 | H52: =E52 | I52: =Parametri!$D$8 | K52: =C52-B52
A53: =A52+1 | B53: 968 | C53: 987 | D53: =IF(C53=0, B53, GEOMEAN(B53:C53)) | E53: =MAX(Parametri!$D$8, ABS(B53-C53)/(2*SQRT(3))) | F53: =(A53-Parametri!$A$11)+Parametri!$A$2+(Parametri!$A$5/2) | G53: =(D53-Parametri!$A$8)-(A53-Parametri!$A$11)+Parametri!$A$2 | H53: =E53 | I53: =Parametri!$D$8 | K53: =C53-B53
A54: =A53+1 | B54: 965 | C54: 974 | D54: =IF(C54=0, B54, GEOMEAN(B54:C54)) | E54: =MAX(Parametri!$D$8, ABS(B54-C54)/(2*SQRT(3))) | F54: =(A54-Parametri!$A$11)+Parametri!$A$2+(Parametri!$A$5/2) | G54: =(D54-Parametri!$A$8)-(A54-Parametri!$A$11)+Parametri!$A$2 | H54: =E54 | I54: =Parametri!$D$8 | K54: =C54-B54
A55: =A54+1 | B55: 960 | C55: 976 | D55: =IF(C55=0, B55, GEOMEAN(B55:C55)) | E55: =MAX(Parametri!$D$8, ABS(B55-C55)/(2*SQRT(3))) | F55: =(A55-Parametri!$A$11)+Parametri!$A$2+(Parametri!$A$5/2) | G55: =(D55-Parametri!$A$8)-(A55-Parametri!$A$11)+Parametri!$A$2 | H55: =E55 | I55: =Parametri!$D$8 | K55: =C55-B55
A56: =A55+1 | B56: 957 | C56: 969 | D56: =IF(C56=0, B56, GEOMEAN(B56:C56)) | E56: =MAX(Parametri!$D$8, ABS(B56-C56)/(2*SQRT(3))) | F56: =(A56-Parametri!$A$11)+Parametri!$A$2+(Parametri!$A$5/2) | G56: =(D56-Parametri!$A$8)-(A56-Parametri!$A$11)+Parametri!$A$2 | H56: =E56 | I56: =Parametri!$D$8 | K56: =C56-B56
A57: =A56+1 | B57: 955 | C57: 967 | D57: =IF(C57=0, B57, GEOMEAN(B57:C57)) | E57: =MAX(Parametri!$D$8, ABS(B57-C57)/(2*SQRT(3))) | F57: =(A57-Parametri!$A$11)+Parametri!$A$2+(Parametri!$A$5/2) | G57: =(D57-Parametri!$A$8)-(A57-Parametri!$A$11)+Parametri!$A$2 | H57: =E57 | I57: =Parametri!$D$8 | K57: =C57-B57
A58: =A57+2 | B58: 945 | C58: 961 | D58: =IF(C58=0, B58, GEOMEAN(B58:C58)) | E58: =MAX(Parametri!$D$8, ABS(B58-C58)/(2*SQRT(3))) | F58: =(A58-Parametri!$A$11)+Parametri!$A$2+(Parametri!$A$5/2) | G58: =(D58-Parametri!$A$8)-(A58-Parametri!$A$11)+Parametri!$A$2 | H58: =E58 | I58: =Parametri!$D$8 | K58: =C58-B58
A59: =A58+2 | B59: 940 | C59: 953 | D59: =IF(C59=0, B59, GEOMEAN(B59:C59)) | E59: =MAX(Parametri!$D$8, ABS(B59-C59)/(2*SQRT(3))) | F59: =(A59-Parametri!$A$11)+Parametri!$A$2+(Parametri!$A$5/2) | G59: =(D59-Parametri!$A$8)-(A59-Parametri!$A$11)+Parametri!$A$2 | H59: =E59 | I59: =Parametri!$D$8 | K59: =C59-B59
...

Sheet Dati
A1: x | B1: y_min | C1: y_max | D1: y | E1: sigma_y | F1: p | G1: q | H1: sigma_p | I1: sigma_q | J1: p-7 | K1: q-7 | L1: p-7 | M1: q-7
A2: 251 | B2: 1802 | C2: 1841 | D2: 1821.3956 | E2: 11.25833 | F2: 232.5 | G2: 1568.3956 | H2: 11.25833 | I2: 0.11547005 | J2: 232.5 | K2: 1568.3956 | L2: 232.5 | M2: 1568.3956
A3: 252 | B3: 1719 | C3: 1836 | D3: 1776.5371 | E3: 33.774991 | F3: 233.5 | G3: 1522.5371 | H3: 33.774991 | I3: 0.11547005 | J3: 233.5 | K3: 1522.5371 | L3: 233.5 | M3: 1522.5371
A4: 253 | B4: 1690 | C4: 1853 | D4: 1769.6243 | E4: 47.054047 | F4: 234.5 | G4: 1514.6243 | H4: 47.054047 | I4: 0.11547005 | J4: 234.5 | K4: 1514.6243 | L4: 234.5 | M4: 1514.6243
A5: 254 | B5: 1630 | C5: 1782 | D5: 1704.3063 | E5: 43.87862 | F5: 235.5 | G5: 1448.3063 | H5: 43.87862 | I5: 0.11547005 | J5: 235.5 | K5: 1448.3063 | L5: 235.5 | M5: 1448.3063
A6: 255 | B6: 1605 | C6: 1745 | D6: 1673.5367 | E6: 40.414519 | F6: 236.5 | G6: 1416.5367 | H6: 40.414519 | I6: 0.11547005 | J6: 236.5 | K6: 1416.5367 | L6: 236.5 | M6: 1416.5367
A7: 256 | B7: 1574 | C7: 1710 | D7: 1640.5914 | E7: 39.259818 | F7: 237.5 | G7: 1382.5914 | H7: 39.259818 | I7: 0.11547005 | J7: 237.5 | K7: 1382.5914 | L7: 237.5 | M7: 1382.5914
A8: 257 | B8: 1546 | C8: 1679 | D8: 1611.1282 | E8: 38.393793 | F8: 238.5 | G8: 1352.1282 | H8: 38.393793 | I8: 0.11547005 | J8: 238.5 | K8: 1352.1282 | L8: 238.5 | M8: 1352.1282
A9: 258 | B9: 1525 | C9: 1629 | D9: 1576.1424 | E9: 30.022214 | F9: 239.5 | G9: 1316.1424 | H9: 30.022214 | I9: 0.11547005 | J9: 239.5 | K9: 1316.1424 | L9: 239.5 | M9: 1316.1424
A10: 259 | B10: 1505 | C10: 1603 | D10: 1553.2273 | E10: 28.290163 | F10: 240.5 | G10: 1292.2273 | H10: 28.290163 | I10: 0.11547005 | J10: 240.5 | K10: 1292.2273 | L10: 240.5 | M10: 1292.2273
A11: 260 | B11: 1467 | C11: 1572 | D11: 1518.5928 | E11: 30.310889 | F11: 241.5 | G11: 1256.5928 | H11: 30.310889 | I11: 0.11547005 | J11: 241.5 | K11: 1256.5928 | L11: 241.5 | M11: 1256.5928
A12: 261 | B12: 1452 | C12: 1534 | D12: 1492.4369 | E12: 23.671361 | F12: 242.5 | G12: 1229.4369 | H12: 23.671361 | I12: 0.11547005 | J12: 242.5 | K12: 1229.4369 | L12: 242.5 | M12: 1229.4369
A13: 262 | B13: 1442 | C13: 1520 | D13: 1480.4864 | E13: 22.51666 | F13: 243.5 | G13: 1216.4864 | H13: 22.51666 | I13: 0.11547005 | J13: 243.5 | K13: 1216.4864 | L13: 243.5 | M13: 1216.4864
... A62: 330 | B62: 906 | C62: 915 | D62: 910.48888 | E62: 2.5980762 | F62: 311.5 | G62: 578.48888 | H62: 2.5980762 | I62: 0.11547005 | J62: 311.5 | K62: 578.48888 | L62: 311.5 | M62: 578.48888
A63: 335 | B63: 886 | D63: 886 | E63: 255.76617 | F63: 316.5 | G63: 549 | H63: 255.76617 | I63: 0.11547005 | J63: 316.5 | K63: 549 | L63: 316.5 | M63: 549
A64: 340 | B64: 871 | D64: 871 | E64: 251.43604 | F64: 321.5 | G64: 529 | H64: 251.43604 | I64: 0.11547005 | J64: 321.5 | K64: 529 | L64: 321.5 | M64: 529
A65: 345 | B65: 870 | D65: 870 | E65: 251.14737 | F65: 326.5 | G65: 523 | H65: 251.14737 | I65: 0.11547005 | J65: 326.5 | K65: 523 | L65: 326.5 | M65: 523
A66: 350 | B66: 864 | D66: 864 | E66: 249.41532 | F66: 331.5 | G66: 512 | H66: 249.41532 | I66: 0.11547005 | J66: 331.5 | K66: 512 | L66: 331.5 | M66: 512
A67: 355 | B67: 856 | D67: 856 | E67: 247.10592 | F67: 336.5 | G67: 499 | H67: 247.10592 | I67: 0.11547005 | J67: 336.5 | K67: 499 | L67: 336.5 | M67: 499
A68: 360 | B68: 851 | D68: 851 | E68: 245.66254 | F68: 341.5 | G68: 489 | H68: 245.66254 | I68: 0.11547005 | J68: 341.5 | K68: 489 | L68: 341.5 | M68: 489
A69: 365 | B69: 846 | D69: 846 | E69: 244.21916 | F69: 346.5 | G69: 479 | H69: 244.21916 | I69: 0.11547005 | J69: 346.5 | K69: 479 | L69: 346.5 | M69: 479
A70: 370 | B70: 840 | D70: 840 | E70: 242.48711 | F70: 351.5 | G70: 468 | H70: 242.48711 | I70: 0.11547005 | J70: 351.5 | K70: 468 | L70: 351.5 | M70: 468
A71: 375 | B71: 835 | D71: 835 | E71: 241.04374 | F71: 356.5 | G71: 458 | H71: 241.04374 | I71: 0.11547005 | J71: 356.5 | K71: 458 | L71: 356.5 | M71: 458
A72: 380 | B72: 833 | D72: 833 | E72: 240.46639 | F72: 361.5 | G72: 451 | H72: 240.46639 | I72: 0.11547005 | J72: 361.5 | K72: 451 | L72: 361.5 | M72: 451
A73: 385 | B73: 832 | D73: 832 | E73: 240.17771 | F73: 366.5 | G73: 445 | H73: 240.17771 | I73: 0.11547005 | J73: 366.5 | K73: 445 | L73: 366.5 | M73: 445
A74: 390 | B74: 828 | D74: 828 | E74: 239.02301 | F74: 371.5 | G74: 436 | H74: 239.02301 | I74: 0.11547005 | J74: 371.5 | K74: 436 | L74: 371.5 | M74: 436
... A117: 1650 | B117: 1882 | D117: 1882 | E117: 543.2866 | F117: 1631.5 | G117: 230 | H117: 543.2866 | I117: 0.11547005 | J117: 1624.5 | K117: 223 | L117: 1624.5 | M117: 223

Sheet Dati (2)
A1: x | B1: y_min | C1: y_max | D1: y_max2 | E1: y | F1: sigma_y | G1: p | H1: q | I1: sigma_p | J1: sigma_q
A2: 270 | D2: =B2+2*E2 | E2: 1975 | F2: =IF(C2=0, Parametri!$D$8, ABS(B2-C2)/(2*SQRT(3))) | G2: =(A2-335)+135.8+(Parametri!$A$5/2) | H2: =(E2-192)-('Dati (2)'!A2-Parametri!$A$11)+Parametri!$A$2 | I2: =F2 | J2: =Parametri!$D$8
A3: =A2+1 | D3: =B3+2*E3 | E3: 1975 | F3: =IF(C3=0, Parametri!$D$8, ABS(B3-C3)/(2*SQRT(3))) | G3: =(A3-335)+135.8+(Parametri!$A$5/2) | H3: =(E3-192)-('Dati (2)'!A3-Parametri!$A$11)+Parametri!$A$2 | I3: =F3 | J3: =Parametri!$D$8
A4: =A3+1 | D4: =B4+2*E4 | E4: 1912 | F4: =IF(C4=0, Parametri!$D$8, ABS(B4-C4)/(2*SQRT(3))) | G4: =(A4-335)+135.8+(Parametri!$A$5/2) | H4: =(E4-192)-('Dati (2)'!A4-Parametri!$A$11)+Parametri!$A$2 | I4: =F4 | J4: =Parametri!$D$8
A5: =A4+1 | D5: =B5+2*E5 | E5: 1893 | F5: =IF(C5=0, Parametri!$D$8, ABS(B5-C5)/(2*SQRT(3))) | G5: =(A5-335)+135.8+(Parametri!$A$5/2) | H5: =(E5-192)-('Dati (2)'!A5-Parametri!$A$11)+Parametri!$A$2 | I5: =F5 | J5: =Parametri!$D$8
A6: =A5+1 | D6: =B6+2*E6 | E6: 1817 | F6: =IF(C6=0, Parametri!$D$8, ABS(B6-C6)/(2*SQRT(3))) | G6: =(A6-335)+135.8+(Parametri!$A$5/2) | H6: =(E6-192)-('Dati (2)'!A6-Parametri!$A$11)+Parametri!$A$2 | I6: =F6 | J6: =Parametri!$D$8
A7: =A6+1 | D7: =B7+2*E7 | E7: 1783 | F7: =IF(C7=0, Parametri!$D$8, ABS(B7-C7)/(2*SQRT(3))) | G7: =(A7-335)+135.8+(Parametri!$A$5/2) | H7: =(E7-192)-('Dati (2)'!A7-Parametri!$A$11)+Parametri!$A$2 | I7: =F7 | J7: =Parametri!$D$8
A8: =A7+1 | D8: =B8+2*E8 | E8: 1723.5 | F8: =IF(C8=0, Parametri!$D$8, ABS(B8-C8)/(2*SQRT(3))) | G8: =(A8-335)+135.8+(Parametri!$A$5/2) | H8: =(E8-192)-('Dati (2)'!A8-Parametri!$A$11)+Parametri!$A$2 | I8: =F8 | J8: =Parametri!$D$8
A9: =A8+1 | D9: =B9+2*E9 | E9: 1676 | F9: =IF(C9=0, Parametri!$D$8, ABS(B9-C9)/(2*SQRT(3))) | G9: =(A9-335)+135.8+(Parametri!$A$5/2) | H9: =(E9-192)-('Dati (2)'!A9-Parametri!$A$11)+Parametri!$A$2 | I9: =F9 | J9: =Parametri!$D$8
A10: =A9+1 | D10: =B10+2*E10 | E10: 1660 | F10: =IF(C10=0, Parametri!$D$8, ABS(B10-C10)/(2*SQRT(3))) | G10: =(A10-335)+135.8+(Parametri!$A$5/2) | H10: =(E10-192)-('Dati (2)'!A10-Parametri!$A$11)+Parametri!$A$2 | I10: =F10 | J10: =Parametri!$D$8
A11: =A10+1 | D11: =B11+2*E11 | E11: 1615.5 | F11: =IF(C11=0, Parametri!$D$8, ABS(B11-C11)/(2*SQRT(3))) | G11: =(A11-335)+135.8+(Parametri!$A$5/2) | H11: =(E11-192)-('Dati (2)'!A11-Parametri!$A$11)+Parametri!$A$2 | I11: =F11 | J11: =Parametri!$D$8
A12: =A11+1 | D12: =B12+2*E12 | E12: 1581.5 | F12: =IF(C12=0, Parametri!$D$8, ABS(B12-C12)/(2*SQRT(3))) | G12: =(A12-335)+135.8+(Parametri!$A$5/2) | H12: =(E12-192)-('Dati (2)'!A12-Parametri!$A$11)+Parametri!$A$2 | I12: =F12 | J12: =Parametri!$D$8
A13: =A12+1 | D13: =B13+2*E13 | E13: 1561 | F13: =IF(C13=0, Parametri!$D$8, ABS(B13-C13)/(2*SQRT(3))) | G13: =(A13-335)+135.8+(Parametri!$A$5/2) | H13: =(E13-192)-('Dati (2)'!A13-Parametri!$A$11)+Parametri!$A$2 | I13: =F13 | J13: =Parametri!$D$8
A14: =A13+1 | D14: =B14+2*E14 | E14: 1533.5 | F14: =IF(C14=0, Parametri!$D$8, ABS(B14-C14)/(2*SQRT(3))) | G14: =(A14-335)+135.8+(Parametri!$A$5/2) | H14: =(E14-192)-('Dati (2)'!A14-Parametri!$A$11)+Parametri!$A$2 | I14: =F14 | J14: =Parametri!$D$8
... A47: =A46+1 | D47: =B47+2*E47 | E47: 1075 | F47: =IF(C47=0, Parametri!$D$8, ABS(B47-C47)/(2*SQRT(3))) | G47: =(A47-335)+135.8+(Parametri!$A$5/2) | H47: =(E47-192)-('Dati (2)'!A47-Parametri!$A$11)+Parametri!$A$2 | I47: =F47 | J47: =Parametri!$D$8
A48: =A47+2 | D48: =B48+2*E48 | E48: 1063 | F48: =IF(C48=0, Parametri!$D$8, ABS(B48-C48)/(2*SQRT(3))) | G48: =(A48-335)+135.8+(Parametri!$A$5/2) | H48: =(E48-192)-('Dati (2)'!A48-Parametri!$A$11)+Parametri!$A$2 | I48: =F48 | J48: =Parametri!$D$8
A49: =A48+2 | D49: =B49+2*E49 | E49: 1042.5 | F49: =IF(C49=0, Parametri!$D$8, ABS(B49-C49)/(2*SQRT(3))) | G49: =(A49-335)+135.8+(Parametri!$A$5/2) | H49: =(E49-192)-('Dati (2)'!A49-Parametri!$A$11)+Parametri!$A$2 | I49: =F49 | J49: =Parametri!$D$8
A50: =A49+2 | D50: =B50+2*E50 | E50: 1034 | F50: =IF(C50=0, Parametri!$D$8, ABS(B50-C50)/(2*SQRT(3))) | G50: =(A50-335)+135.8+(Parametri!$A$5/2) | H50: =(E50-192)-('Dati (2)'!A50-Parametri!$A$11)+Parametri!$A$2 | I50: =F50 | J50: =Parametri!$D$8
A51: =A50+2 | D51: =B51+2*E51 | E51: 1027.5 | F51: =IF(C51=0, Parametri!$D$8, ABS(B51-C51)/(2*SQRT(3))) | G51: =(A51-335)+135.8+(Parametri!$A$5/2) | H51: =(E51-192)-('Dati (2)'!A51-Parametri!$A$11)+Parametri!$A$2 | I51: =F51 | J51: =Parametri!$D$8
A52: =A51+2 | D52: =B52+2*E52 | E52: 1010 | F52: =IF(C52=0, Parametri!$D$8, ABS(B52-C52)/(2*SQRT(3))) | G52: =(A52-335)+135.8+(Parametri!$A$5/2) | H52: =(E52-192)-('Dati (2)'!A52-Parametri!$A$11)+Parametri!$A$2 | I52: =F52 | J52: =Parametri!$D$8
A53: =A52+2 | D53: =B53+2*E53 | E53: 999.5 | F53: =IF(C53=0, Parametri!$D$8, ABS(B53-C53)/(2*SQRT(3))) | G53: =(A53-335)+135.8+(Parametri!$A$5/2) | H53: =(E53-192)-('Dati (2)'!A53-Parametri!$A$11)+Parametri!$A$2 | I53: =F53 | J53: =Parametri!$D$8
A54: =A53+2 | D54: =B54+2*E54 | E54: 987.5 | F54: =IF(C54=0, Parametri!$D$8, ABS(B54-C54)/(2*SQRT(3))) | G54: =(A54-335)+135.8+(Parametri!$A$5/2) | H54: =(E54-192)-('Dati (2)'!A54-Parametri!$A$11)+Parametri!$A$2 | I54: =F54 | J54: =Parametri!$D$8
A55: =A54+2 | D55: =B55+2*E55 | E55: 980.5 | F55: =IF(C55=0, Parametri!$D$8, ABS(B55-C55)/(2*SQRT(3))) | G55: =(A55-335)+135.8+(Parametri!$A$5/2) | H55: =(E55-192)-('Dati (2)'!A55-Parametri!$A$11)+Parametri!$A$2 | I55: =F55 | J55: =Parametri!$D$8
A56: =A55+2 | D56: =B56+2*E56 | E56: 970 | F56: =IF(C56=0, Parametri!$D$8, ABS(B56-C56)/(2*SQRT(3))) | G56: =(A56-335)+135.8+(Parametri!$A$5/2) | H56: =(E56-192)-('Dati (2)'!A56-Parametri!$A$11)+Parametri!$A$2 | I56: =F56 | J56: =Parametri!$D$8
A57: =A56+2 | D57: =B57+2*E57 | E57: 955 | F57: =IF(C57=0, Parametri!$D$8, ABS(B57-C57)/(2*SQRT(3))) | G57: =(A57-335)+135.8+(Parametri!$A$5/2) | H57: =(E57-192)-('Dati (2)'!A57-Parametri!$A$11)+Parametri!$A$2 | I57: =F57 | J57: =Parametri!$D$8
A58: =A57+2 | D58: =B58+2*E58 | E58: 945.5 | F58: =IF(C58=0, Parametri!$D$8, ABS(B58-C58)/(2*SQRT(3))) | G58: =(A58-335)+135.8+(Parametri!$A$5/2) | H58: =(E58-192)-('Dati (2)'!A58-Parametri!$A$11)+Parametri!$A$2 | I58: =F58 | J58: =Parametri!$D$8
A59: =A58+2 | D59: =B59+2*E59 | E59: 943.5 | F59: =IF(C59=0, Parametri!$D$8, ABS(B59-C59)/(2*SQRT(3))) | G59: =(A59-335)+135.8+(Parametri!$A$5/2) | H59: =(E59-192)-('Dati (2)'!A59-Parametri!$A$11)+Parametri!$A$2 | I59: =F59 | J59: =Parametri!$D$8
... A65: =A64+2 | D65: =B65+2*E65 | E65: 906 | F65: =IF(C65=0, Parametri!$D$8, ABS(B65-C65)/(2*SQRT(3))) | G65: =(A65-335)+135.8+(Parametri!$A$5/2) | H65: =(E65-192)-('Dati (2)'!A65-Parametri!$A$11)+Parametri!$A$2 | I65: =F65 | J65: =Parametri!$D$8
A66: =A65+3 | D66: =B66+2*E66 | E66: 903 | F66: =IF(C66=0, Parametri!$D$8, ABS(B66-C66)/(2*SQRT(3))) | G66: =(A66-335)+135.8+(Parametri!$A$5/2) | H66: =(E66-192)-('Dati (2)'!A66-Parametri!$A$11)+Parametri!$A$2 | I66: =F66 | J66: =Parametri!$D$8
A67: =A66+3 | D67: =B67+2*E67 | E67: 891 | F67: =IF(C67=0, Parametri!$D$8, ABS(B67-C67)/(2*SQRT(3))) | G67: =(A67-335)+135.8+(Parametri!$A$5/2) | H67: =(E67-192)-('Dati (2)'!A67-Parametri!$A$11)+Parametri!$A$2 | I67: =F67 | J67: =Parametri!$D$8
A68: =A67+3 | D68: =B68+2*E68 | E68: 888.5 | F68: =IF(C68=0, Parametri!$D$8, ABS(B68-C68)/(2*SQRT(3))) | G68: =(A68-335)+135.8+(Parametri!$A$5/2) | H68: =(E68-192)-('Dati (2)'!A68-Parametri!$A$11)+Parametri!$A$2 | I68: =F68 | J68: =Parametri!$D$8
A69: =A68+3 | D69: =B69+2*E69 | E69: 890 | F69: =IF(C69=0, Parametri!$D$8, ABS(B69-C69)/(2*SQRT(3))) | G69: =(A69-335)+135.8+(Parametri!$A$5/2) | H69: =(E69-192)-('Dati (2)'!A69-Parametri!$A$11)+Parametri!$A$2 | I69: =F69 | J69: =Parametri!$D$8
A70: =A69+3 | D70: =B70+2*E70 | E70: 876 | F70: =IF(C70=0, Parametri!$D$8, ABS(B70-C70)/(2*SQRT(3))) | G70: =(A70-335)+135.8+(Parametri!$A$5/2) | H70: =(E70-192)-('Dati (2)'!A70-Parametri!$A$11)+Parametri!$A$2 | I70: =F70 | J70: =Parametri!$D$8
A71: =A70+3 | D71: =B71+2*E71 | E71: 872 | F71: =IF(C71=0, Parametri!$D$8, ABS(B71-C71)/(2*SQRT(3))) | G71: =(A71-335)+135.8+(Parametri!$A$5/2) | H71: =(E71-192)-('Dati (2)'!A71-Parametri!$A$11)+Parametri!$A$2 | I71: =F71 | J71: =Parametri!$D$8
A72: =A71+3 | D72: =B72+2*E72 | E72: 871 | F72: =IF(C72=0, Parametri!$D$8, ABS(B72-C72)/(2*SQRT(3))) | G72: =(A72-335)+135.8+(Parametri!$A$5/2) | H72: =(E72-192)-('Dati (2)'!A72-Parametri!$A$11)+Parametri!$A$2 | I72: =F72 | J72: =Parametri!$D$8
A73: =A72+3 | D73: =B73+2*E73 | E73: 867 | F73: =IF(C73=0, Parametri!$D$8, ABS(B73-C73)/(2*SQRT(3))) | G73: =(A73-335)+135.8+(Parametri!$A$5/2) | H73: =(E73-192)-('Dati (2)'!A73-Parametri!$A$11)+Parametri!$A$2 | I73: =F73 | J73: =Parametri!$D$8
A74: =A73+4 | D74: =B74+2*E74 | E74: 860.5 | F74: =IF(C74=0, Parametri!$D$8, ABS(B74-C74)/(2*SQRT(3))) | G74: =(A74-335)+135.8+(Parametri!$A$5/2) | H74: =(E74-192)-('Dati (2)'!A74-Parametri!$A$11)+Parametri!$A$2 | I74: =F74 | J74: =Parametri!$D$8
A75: =A74+4 | D75: =B75+2*E75 | E75: 860 | F75: =IF(C75=0, Parametri!$D$8, ABS(B75-C75)/(2*SQRT(3))) | G75: =(A75-335)+135.8+(Parametri!$A$5/2) | H75: =(E75-192)-('Dati (2)'!A75-Parametri!$A$11)+Parametri!$A$2 | I75: =F75 | J75: =Parametri!$D$8
A76: =A75+4 | D76: =B76+2*E76 | E76: 853 | F76: =IF(C76=0, Parametri!$D$8, ABS(B76-C76)/(2*SQRT(3))) | G76: =(A76-335)+135.8+(Parametri!$A$5/2) | H76: =(E76-192)-('Dati (2)'!A76-Parametri!$A$11)+Parametri!$A$2 | I76: =F76 | J76: =Parametri!$D$8
A77: =A76+4 | D77: =B77+2*E77 | E77: 847.5 | F77: =IF(C77=0, Parametri!$D$8, ABS(B77-C77)/(2*SQRT(3))) | G77: =(A77-335)+135.8+(Parametri!$A$5/2) | H77: =(E77-192)-('Dati (2)'!A77-Parametri!$A$11)+Parametri!$A$2 | I77: =F77 | J77: =Parametri!$D$8
...
