Workbook

Sheet Parametri
A1: L | B1: err_L | C1: sigma_L
A4: D | B4: err_D | C4: sigma_D
A7: y_0 | B7: err_y0 | C7: sigma_y0 | D7: sigma_y
B8: 0.2 | C8: =B8/SQRT(3) -> 0.11547005 | D8: =B8/SQRT(3) -> 0.11547005
A10: x_0 | B10: err_x0 | C10: sigma_x0 | D10: sigma_x
B11: 0.2 | C11: =B11/SQRT(3) -> 0.11547005 | D11: =B11/SQRT(3) -> 0.11547005

Sheet Dati (2)
A1: x | B1: y_min | C1: y_max | D1: y_max2 | E1: y | F1: sigma_y | G1: p | H1: q | I1: sigma_p | J1: sigma_q
A2: 270 | D2: =B2+2*E2 -> 3950 | E2: 1975 | F2: =IF(C2=0, Parametri!$D$8, ABS(B2-C2)/(2*SQRT(3))) -> 0.11547005 | G2: =(A2-335)+135.8+(Parametri!$A$5/2) -> 70.8 | H2: =(E2-192)-('Dati (2)'!A2-Parametri!$A$11)+Parametri!$A$2 -> 1513 | I2: =F2 -> 0.11547005 | J2: =Parametri!$D$8 -> 0.11547005
A3: =A2+1 -> 271 | D3: =B3+2*E3 -> 3950 | E3: 1975 | F3: =IF(C3=0, Parametri!$D$8, ABS(B3-C3)/(2*SQRT(3))) -> 0.11547005 | G3: =(A3-335)+135.8+(Parametri!$A$5/2) -> 71.8 | H3: =(E3-192)-('Dati (2)'!A3-Parametri!$A$11)+Parametri!$A$2 -> 1512 | I3: =F3 -> 0.11547005 | J3: =Parametri!$D$8 -> 0.11547005
A4: =A3+1 -> 272 | D4: =B4+2*E4 -> 3824 | E4: 1912 | F4: =IF(C4=0, Parametri!$D$8, ABS(B4-C4)/(2*SQRT(3))) -> 0.11547005 | G4: =(A4-335)+135.8+(Parametri!$A$5/2) -> 72.8 | H4: =(E4-192)-('Dati (2)'!A4-Parametri!$A$11)+Parametri!$A$2 -> 1448 | I4: =F4 -> 0.11547005 | J4: =Parametri!$D$8 -> 0.11547005
A5: =A4+1 -> 273 | D5: =B5+2*E5 -> 3786 | E5: 1893 | F5: =IF(C5=0, Parametri!$D$8, ABS(B5-C5)/(2*SQRT(3))) -> 0.11547005 | G5: =(A5-335)+135.8+(Parametri!$A$5/2) -> 73.8 | H5: =(E5-192)-('Dati (2)'!A5-Parametri!$A$11)+Parametri!$A$2 -> 1428 | I5: =F5 -> 0.11547005 | J5: =Parametri!$D$8 -> 0.11547005
A6: =A5+1 -> 274 | D6: =B6+2*E6 -> 3634 | E6: 1817 | F6: =IF(C6=0, Parametri!$D$8, ABS(B6-C6)/(2*SQRT(3))) -> 0.11547005 | G6: =(A6-335)+135.8+(Parametri!$A$5/2) -> 74.8 | H6: =(E6-192)-('Dati (2)'!A6-Parametri!$A$11)+Parametri!$A$2 -> 1351 | I6: =F6 -> 0.11547005 | J6: =Parametri!$D$8 -> 0.11547005
A7: =A6+1 -> 275 | D7: =B7+2*E7 -> 3566 | E7: 1783 | F7: =IF(C7=0, Parametri!$D$8, ABS(B7-C7)/(2*SQRT(3))) -> 0.11547005 | G7: =(A7-335)+135.8+(Parametri!$A$5/2) -> 75.8 | H7: =(E7-192)-('Dati (2)'!A7-Parametri!$A$11)+Parametri!$A$2 -> 1316 | I7: =F7 -> 0.11547005 | J7: =Parametri!$D$8 -> 0.11547005
A8: =A7+1 -> 276 | D8: =B8+2*E8 -> 3447 | E8: 1723.5 | F8: =IF(C8=0, Parametri!$D$8, ABS(B8-C8)/(2*SQRT(3))) -> 0.11547005 | G8: =(A8-335)+135.8+(Parametri!$A$5/2) -> 76.8 | H8: =(E8-192)-('Dati (2)'!A8-Parametri!$A$11)+Parametri!$A$2 -> 1255.5 | I8: =F8 -> 0.11547005 | J8: =Parametri!$D$8 -> 0.11547005
A9: =A8+1 -> 277 | D9: =B9+2*E9 -> 3352 | E9: 1676 | F9: =IF(C9=0, Parametri!$D$8, ABS(B9-C9)/(2*SQRT(3))) -> 0.11547005 | G9: =(A9-335)+135.8+(Parametri!$A$5/2) -> 77.8 | H9: =(E9-192)-('Dati (2)'!A9-Parametri!$A$11)+Parametri!$A$2 -> 1207 | I9: =F9 -> 0.11547005 | J9: =Parametri!$D$8 -> 0.11547005
A10: =A9+1 -> 278 | D10: =B10+2*E10 -> 3320 | E10: 1660 | F10: =IF(C10=0, Parametri!$D$8, ABS(B10-C10)/(2*SQRT(3))) -> 0.11547005 | G10: =(A10-335)+135.8+(Parametri!$A$5/2) -> 78.8 | H10: =(E10-192)-('Dati (2)'!A10-Parametri!$A$11)+Parametri!$A$2 -> 1190 | I10: =F10 -> 0.11547005 | J10: =Parametri!$D$8 -> 0.11547005
A11: =A10+1 -> 279 | D11: =B11+2*E11 -> 3231 | E11: 1615.5 | F11: =IF(C11=0, Parametri!$D$8, ABS(B11-C11)/(2*SQRT(3))) -> 0.11547005 | G11: =(A11-335)+135.8+(Parametri!$A$5/2) -> 79.8 | H11: =(E11-192)-('Dati (2)'!A11-Parametri!$A$11)+Parametri!$A$2 -> 1144.5 | I11: =F11 -> 0.11547005 | J11: =Parametri!$D$8 -> 0.11547005
A12: =A11+1 -> 280 | D12: =B12+2*E12 -> 3163 | E12: 1581.5 | F12: =IF(C12=0, Parametri!$D$8, ABS(B12-C12)/(2*SQRT(3))) -> 0.11547005 | G12: =(A12-335)+135.8+(Parametri!$A$5/2) -> 80.8 | H12: =(E12-192)-('Dati (2)'!A12-Parametri!$A$11)+Parametri!$A$2 -> 1109.5 | I12: =F12 -> 0.11547005 | J12: =Parametri!$D$8 -> 0.11547005
A13: =A12+1 -> 281 | D13: =B13+2*E13 -> 3122 | E13: 1561 | F13: =IF(C13=0, Parametri!$D$8, ABS(B13-C13)/(2*SQRT(3))) -> 0.11547005 | G13: =(A13-335)+135.8+(Parametri!$A$5/2) -> 81.8 | H13: =(E13-192)-('Dati (2)'!A13-Parametri!$A$11)+Parametri!$A$2 -> 1088 | I13: =F13 -> 0.11547005 | J13: =Parametri!$D$8 -> 0.11547005
A14: =A13+1 -> 282 | D14: =B14+2*E14 -> 3067 | E14: 1533.5 | F14: =IF(C14=0, Parametri!$D$8, ABS(B14-C14)/(2*SQRT(3))) -> 0.11547005 | G14: =(A14-335)+135.8+(Parametri!$A$5/2) -> 82.8 | H14: =(E14-192)-('Dati (2)'!A14-Parametri!$A$11)+Parametri!$A$2 -> 1059.5 | I14: =F14 -> 0.11547005 | J14: =Parametri!$D$8 -> 0.11547005
... A47: =A46+1 -> 315 | D47: =B47+2*E47 -> 2150 | E47: 1075 | F47: =IF(C47=0, Parametri!$D$8, ABS(B47-C47)/(2*SQRT(3))) -> 0.11547005 | G47: =(A47-335)+135.8+(Parametri!$A$5/2) -> 115.8 | H47: =(E47-192)-('Dati (2)'!A47-Parametri!$A$11)+Parametri!$A$2 -> 568 | I47: =F47 -> 0.11547005 | J47: =Parametri!$D$8 -> 0.11547005
A48: =A47+2 -> 317 | D48: =B48+2*E48 -> 2126 | E48: 1063 | F48: =IF(C48=0, Parametri!$D$8, ABS(B48-C48)/(2*SQRT(3))) -> 0.11547005 | G48: =(A48-335)+135.8+(Parametri!$A$5/2) -> 117.8 | H48: =(E48-192)-('Dati (2)'!A48-Parametri!$A$11)+Parametri!$A$2 -> 554 | I48: =F48 -> 0.11547005 | J48: =Parametri!$D$8 -> 0.11547005
A49: =A48+2 -> 319 | D49: =B49+2*E49 -> 2085 | E49: 1042.5 | F49: =IF(C49=0, Parametri!$D$8, ABS(B49-C49)/(2*SQRT(3))) -> 0.11547005 | G49: =(A49-335)+135.8+(Parametri!$A$5/2) -> 119.8 | H49: =(E49-192)-('Dati (2)'!A49-Parametri!$A$11)+Parametri!$A$2 -> 531.5 | I49: =F49 -> 0.11547005 | J49: =Parametri!$D$8 -> 0.11547005
A50: =A49+2 -> 321 | D50: =B50+2*E50 -> 2068 | E50: 1034 | F50: =IF(C50=0, Parametri!$D$8, ABS(B50-C50)/(2*SQRT(3))) -> 0.11547005 | G50: =(A50-335)+135.8+(Parametri!$A$5/2) -> 121.8 | H50: =(E50-192)-('Dati (2)'!A50-Parametri!$A$11)+Parametri!$A$2 -> 521 | I50: =F50 -> 0.11547005 | J50: =Parametri!$D$8 -> 0.11547005
A51: =A50+2 -> 323 | D51: =B51+2*E51 -> 2055 | E51: 1027.5 | F51: =IF(C51=0, Parametri!$D$8, ABS(B51-C51)/(2*SQRT(3))) -> 0.11547005 | G51: =(A51-335)+135.8+(Parametri!$A$5/2) -> 123.8 | H51: =(E51-192)-('Dati (2)'!A51-Parametri!$A$11)+Parametri!$A$2 -> 512.5 | I51: =F51 -> 0.11547005 | J51: =Parametri!$D$8 -> 0.11547005
A52: =A51+2 -> 325 | D52: =B52+2*E52 -> 2020 | E52: 1010 | F52: =IF(C52=0, Parametri!$D$8, ABS(B52-C52)/(2*SQRT(3))) -> 0.11547005 | G52: =(A52-335)+135.8+(Parametri!$A$5/2) -> 125.8 | H52: =(E52-192)-('Dati (2)'!A52-Parametri!$A$11)+Parametri!$A$2 -> 493 | I52: =F52 -> 0.11547005 | J52: =Parametri!$D$8 -> 0.11547005
A53: =A52+2 -> 327 | D53: =B53+2*E53 -> 1999 | E53: 999.5 | F53: =IF(C53=0, Parametri!$D$8, ABS(B53-C53)/(2*SQRT(3))) -> 0.11547005 | G53: =(A53-335)+135.8+(Parametri!$A$5/2) -> 127.8 | H53: =(E53-192)-('Dati (2)'!A53-Parametri!$A$11)+Parametri!$A$2 -> 480.5 | I53: =F53 -> 0.11547005 | J53: =Parametri!$D$8 -> 0.11547005
A54: =A53+2 -> 329 | D54: =B54+2*E54 -> 1975 | E54: 987.5 | F54: =IF(C54=0, Parametri!$D$8, ABS(B54-C54)/(2*SQRT(3))) -> 0.11547005 | G54: =(A54-335)+135.8+(Parametri!$A$5/2) -> 129.8 | H54: =(E54-192)-('Dati (2)'!A54-Parametri!$A$11)+Parametri!$A$2 -> 466.5 | I54: =F54 -> 0.11547005 | J54: =Parametri!$D$8 -> 0.11547005
A55: =A54+2 -> 331 | D55: =B55+2*E55 -> 1961 | E55: 980.5 | F55: =IF(C55=0, Parametri!$D$8, ABS(B55-C55)/(2*SQRT(3))) -> 0.11547005 | G55: =(A55-335)+135.8+(Parametri!$A$5/2) -> 131.8 | H55: =(E55-192)-('Dati (2)'!A55-Parametri!$A$11)+Parametri!$A$2 -> 457.5 | I55: =F55 -> 0.11547005 | J55: =Parametri!$D$8 -> 0.11547005
A56: =A55+2 -> 333 | D56: =B56+2*E56 -> 1940 | E56: 970 | F56: =IF(C56=0, Parametri!$D$8, ABS(B56-C56)/(2*SQRT(3))) -> 0.11547005 | G56: =(A56-335)+135.8+(Parametri!$A$5/2) -> 133.8 | H56: =(E56-192)-('Dati (2)'!A56-Parametri!$A$11)+Parametri!$A$2 -> 445 | I56: =F56 -> 0.11547005 | J56: =Parametri!$D$8 -> 0.11547005
A57: =A56+2 -> 335 | D57: =B57+2*E57 -> 1910 | E57: 955 | F57: =IF(C57=0, Parametri!$D$8, ABS(B57-C57)/(2*SQRT(3))) -> 0.11547005 | G57: =(A57-335)+135.8+(Parametri!$A$5/2) -> 135.8 | H57: =(E57-192)-('Dati (2)'!A57-Parametri!$A$11)+Parametri!$A$2 -> 428 | I57: =F57 -> 0.11547005 | J57: =Parametri!$D$8 -> 0.11547005
A58: =A57+2 -> 337 | D58: =B58+2*E58 -> 1891 | E58: 945.5 | F58: =IF(C58=0, Parametri!$D$8, ABS(B58-C58)/(2*SQRT(3))) -> 0.11547005 | G58: =(A58-335)+135.8+(Parametri!$A$5/2) -> 137.8 | H58: =(E58-192)-('Dati (2)'!A58-Parametri!$A$11)+Parametri!$A$2 -> 416.5 | I58: =F58 -> 0.11547005 | J58: =Parametri!$D$8 -> 0.11547005
A59: =A58+2 -> 339 | D59: =B59+2*E59 -> 1887 | E59: 943.5 | F59: =IF(C59=0, Parametri!$D$8, ABS(B59-C59)/(2*SQRT(3))) -> 0.11547005 | G59: =(A59-335)+135.8+(Parametri!$A$5/2) -> 139.8 | H59: =(E59-192)-('Dati (2)'!A59-Parametri!$A$11)+Parametri!$A$2 -> 412.5 | I59: =F59 -> 0.11547005 | J59: =Parametri!$D$8 -> 0.11547005
... A65: =A64+2 -> 351 | D65: =B65+2*E65 -> 1812 | E65: 906 | F65: =IF(C65=0, Parametri!$D$8, ABS(B65-C65)/(2*SQRT(3))) -> 0.11547005 | G65: =(A65-335)+135.8+(Parametri!$A$5/2) -> 151.8 | H65: =(E65-192)-('Dati (2)'!A65-Parametri!$A$11)+Parametri!$A$2 -> 363 | I65: =F65 -> 0.11547005 | J65: =Parametri!$D$8 -> 0.11547005
A66: =A65+3 -> 354 | D66: =B66+2*E66 -> 1806 | E66: 903 | F66: =IF(C66=0, Parametri!$D$8, ABS(B66-C66)/(2*SQRT(3))) -> 0.11547005 | G66: =(A66-335)+135.8+(Parametri!$A$5/2) -> 154.8 | H66: =(E66-192)-('Dati (2)'!A66-Parametri!$A$11)+Parametri!$A$2 -> 357 | I66: =F66 -> 0.11547005 | J66: =Parametri!$D$8 -> 0.11547005
A67: =A66+3 -> 357 | D67: =B67+2*E67 -> 1782 | E67: 891 | F67: =IF(C67=0, Parametri!$D$8, ABS(B67-C67)/(2*SQRT(3))) -> 0.11547005 | G67: =(A67-335)+135.8+(Parametri!$A$5/2) -> 157.8 | H67: =(E67-192)-('Dati (2)'!A67-Parametri!$A$11)+Parametri!$A$2 -> 342 | I67: =F67 -> 0.11547005 | J67: =Parametri!$D$8 -> 0.11547005
A68: =A67+3 -> 360 | D68: =B68+2*E68 -> 1777 | E68: 888.5 | F68: =IF(C68=0, Parametri!$D$8, ABS(B68-C68)/(2*SQRT(3))) -> 0.11547005 | G68: =(A68-335)+135.8+(Parametri!$A$5/2) -> 160.8 | H68: =(E68-192)-('Dati (2)'!A68-Parametri!$A$11)+Parametri!$A$2 -> 336.5 | I68: =F68 -> 0.11547005 | J68: =Parametri!$D$8 -> 0.11547005
A69: =A68+3 -> 363 | D69: =B69+2*E69 -> 1780 | E69: 890 | F69: =IF(C69=0, Parametri!$D$8, ABS(B69-C69)/(2*SQRT(3))) -> 0.11547005 | G69: =(A69-335)+135.8+(Parametri!$A$5/2) -> 163.8 | H69: =(E69-192)-('Dati (2)'!A69-Parametri!$A$11)+Parametri!$A$2 -> 335 | I69: =F69 -> 0.11547005 | J69: =Parametri!$D$8 -> 0.11547005
A70: =A69+3 -> 366 | D70: =B70+2*E70 -> 1752 | E70: 876 | F70: =IF(C70=0, Parametri!$D$8, ABS(B70-C70)/(2*SQRT(3))) -> 0.11547005 | G70: =(A70-335)+135.8+(Parametri!$A$5/2) -> 166.8 | H70: =(E70-192)-('Dati (2)'!A70-Parametri!$A$11)+Parametri!$A$2 -> 318 | I70: =F70 -> 0.11547005 | J70: =Parametri!$D$8 -> 0.11547005
A71: =A70+3 -> 369 | D71: =B71+2*E71 -> 1744 | E71: 872 | F71: =IF(C71=0, Parametri!$D$8, ABS(B71-C71)/(2*SQRT(3))) -> 0.11547005 | G71: =(A71-335)+135.8+(Parametri!$A$5/2) -> 169.8 | H71: =(E71-192)-('Dati (2)'!A71-Parametri!$A$11)+Parametri!$A$2 -> 311 | I71: =F71 -> 0.11547005 | J71: =Parametri!$D$8 -> 0.11547005
A72: =A71+3 -> 372 | D72: =B72+2*E72 -> 1742 | E72: 871 | F72: =IF(C72=0, Parametri!$D$8, ABS(B72-C72)/(2*SQRT(3))) -> 0.11547005 | G72: =(A72-335)+135.8+(Parametri!$A$5/2) -> 172.8 | H72: =(E72-192)-('Dati (2)'!A72-Parametri!$A$11)+Parametri!$A$2 -> 307 | I72: =F72 -> 0.11547005 | J72: =Parametri!$D$8 -> 0.11547005
A73: =A72+3 -> 375 | D73: =B73+2*E73 -> 1734 | E73: 867 | F73: =IF(C73=0, Parametri!$D$8, ABS(B73-C73)/(2*SQRT(3))) -> 0.11547005 | G73: =(A73-335)+135.8+(Parametri!$A$5/2) -> 175.8 | H73: =(E73-192)-('Dati (2)'!A73-Parametri!$A$11)+Parametri!$A$2 -> 300 | I73: =F73 -> 0.11547005 | J73: =Parametri!$D$8 -> 0.11547005
A74: =A73+4 -> 379 | D74: =B74+2*E74 -> 1721 | E74: 860.5 | F74: =IF(C74=0, Parametri!$D$8, ABS(B74-C74)/(2*SQRT(3))) -> 0.11547005 | G74: =(A74-335)+135.8+(Parametri!$A$5/2) -> 179.8 | H74: =(E74-192)-('Dati (2)'!A74-Parametri!$A$11)+Parametri!$A$2 -> 289.5 | I74: =F74 -> 0.11547005 | J74: =Parametri!$D$8 -> 0.11547005
A75: =A74+4 -> 383 | D75: =B75+2*E75 -> 1720 | E75: 860 | F75: =IF(C75=0, Parametri!$D$8, ABS(B75-C75)/(2*SQRT(3))) -> 0.11547005 | G75: =(A75-335)+135.8+(Parametri!$A$5/2) -> 183.8 | H75: =(E75-192)-('Dati (2)'!A75-Parametri!$A$11)+Parametri!$A$2 -> 285 | I75: =F75 -> 0.11547005 | J75: =Parametri!$D$8 -> 0.11547005
A76: =A75+4 -> 387 | D76: =B76+2*E76 -> 1706 | E76: 853 | F76: =IF(C76=0, Parametri!$D$8, ABS(B76-C76)/(2*SQRT(3))) -> 0.11547005 | G76: =(A76-335)+135.8+(Parametri!$A$5/2) -> 187.8 | H76: =(E76-192)-('Dati (2)'!A76-Parametri!$A$11)+Parametri!$A$2 -> 274 | I76: =F76 -> 0.11547005 | J76: =Parametri!$D$8 -> 0.11547005
A77: =A76+4 -> 391 | D77: =B77+2*E77 -> 1695 | E77: 847.5 | F77: =IF(C77=0, Parametri!$D$8, ABS(B77-C77)/(2*SQRT(3))) -> 0.11547005 | G77: =(A77-335)+135.8+(Parametri!$A$5/2) -> 191.8 | H77: =(E77-192)-('Dati (2)'!A77-Parametri!$A$11)+Parametri!$A$2 -> 264.5 | I77: =F77 -> 0.11547005 | J77: =Parametri!$D$8 -> 0.11547005
...

Sheet Dati
A1: x | B1: y_min | C1: y_max | D1: y | E1: sigma_y | F1: p | G1: q | H1: sigma_p | I1: sigma_q
A2: 251 | B2: 1802 | C2: 1841 | D2: 1821.3956 | E2: 11.25833 | F2: 232.5 | G2: 1568.3956 | H2: 0.11547005 | I2: 11.25833
A3: 252 | B3: 1719 | C3: 1836 | D3: 1776.5371 | E3: 33.774991 | F3: 233.5 | G3: 1522.5371 | H3: 0.11547005 | I3: 33.774991
A4: 253 | B4: 1690 | C4: 1853 | D4: 1769.6243 | E4: 47.054047 | F4: 234.5 | G4: 1514.6243 | H4: 0.11547005 | I4: 47.054047
A5: 254 | B5: 1630 | C5: 1782 | D5: 1704.3063 | E5: 43.87862 | F5: 235.5 | G5: 1448.3063 | H5: 0.11547005 | I5: 43.87862
A6: 255 | B6: 1605 | C6: 1745 | D6: 1673.5367 | E6: 40.414519 | F6: 236.5 | G6: 1416.5367 | H6: 0.11547005 | I6: 40.414519
A7: 256 | B7: 1574 | C7: 1710 | D7: 1640.5914 | E7: 39.259818 | F7: 237.5 | G7: 1382.5914 | H7: 0.11547005 | I7: 39.259818
A8: 257 | B8: 1546 | C8: 1679 | D8: 1611.1282 | E8: 38.393793 | F8: 238.5 | G8: 1352.1282 | H8: 0.11547005 | I8: 38.393793
A9: 258 | B9: 1525 | C9: 1629 | D9: 1576.1424 | E9: 30.022214 | F9: 239.5 | G9: 1316.1424 | H9: 0.11547005 | I9: 30.022214
A10: 259 | B10: 1505 | C10: 1603 | D10: 1553.2273 | E10: 28.290163 | F10: 240.5 | G10: 1292.2273 | H10: 0.11547005 | I10: 28.290163
A11: 260 | B11: 1467 | C11: 1572 | D11: 1518.5928 | E11: 30.310889 | F11: 241.5 | G11: 1256.5928 | H11: 0.11547005 | I11: 30.310889
A12: 261 | B12: 1452 | C12: 1534 | D12: 1492.4369 | E12: 23.671361 | F12: 242.5 | G12: 1229.4369 | H12: 0.11547005 | I12: 23.671361
A13: 262 | B13: 1442 | C13: 1520 | D13: 1480.4864 | E13: 22.51666 | F13: 243.5 | G13: 1216.4864 | H13: 0.11547005 | I13: 22.51666
... A62: 330 | B62: 906 | C62: 915 | D62: 910.48888 | E62: 2.5980762 | F62: 311.5 | G62: 578.48888 | H62: 0.11547005 | I62: 2.5980762
A63: 335 | B63: 886 | D63: 886 | E63: 0.11547005 | F63: 316.5 | G63: 549 | H63: 0.11547005 | I63: 0.11547005
A64: 340 | B64: 871 | D64: 871 | E64: 0.11547005 | F64: 321.5 | G64: 529 | H64: 0.11547005 | I64: 0.11547005
A65: 345 | B65: 870 | D65: 870 | E65: 0.11547005 | F65: 326.5 | G65: 523 | H65: 0.11547005 | I65: 0.11547005
A66: 350 | B66: 864 | D66: 864 | E66: 0.11547005 | F66: 331.5 | G66: 512 | H66: 0.11547005 | I66: 0.11547005
A67: 355 | B67: 856 | D67: 856 | E67: 0.11547005 | F67: 336.5 | G67: 499 | H67: 0.11547005 | I67: 0.11547005
A68: 360 | B68: 851 | D68: 851 | E68: 0.11547005 | F68: 341.5 | G68: 489 | H68: 0.11547005 | I68: 0.11547005
A69: 365 | B69: 846 | D69: 846 | E69: 0.11547005 | F69: 346.5 | G69: 479 | H69: 0.11547005 | I69: 0.11547005
A70: 370 | B70: 840 | D70: 840 | E70: 0.11547005 | F70: 351.5 | G70: 468 | H70: 0.11547005 | I70: 0.11547005
A71: 375 | B71: 835 | D71: 835 | E71: 0.11547005 | F71: 356.5 | G71: 458 | H71: 0.11547005 | I71: 0.11547005
A72: 380 | B72: 833 | D72: 833 | E72: 0.11547005 | F72: 361.5 | G72: 451 | H72: 0.11547005 | I72: 0.11547005
A73: 385 | B73: 832 | D73: 832 | E73: 0.11547005 | F73: 366.5 | G73: 445 | H73: 0.11547005 | I73: 0.11547005
A74: 390 | B74: 828 | D74: 828 | E74: 0.11547005 | F74: 371.5 | G74: 436 | H74: 0.11547005 | I74: 0.11547005
... A117: 1650 | B117: 1882 | D117: 1882 | E117: 0.11547005 | F117: 1631.5 | G117: 230 | H117: 0.11547005 | I117: 0.11547005

Sheet Data
A1: x | B1: y_min | C1: y_max | D1: y | E1: sigma_y | F1: p | G1: q | H1: sigma_p | I1: sigma_q
A2: 251 | B2: 1802 | C2: 1841 | D2: 1821.3956 | E2: 11.25833 | F2: 232.5 | G2: 1568.3956 | H2: 11.25833 | I2: 0.11547005
A3: 252 | B3: 1719 | C3: 1836 | D3: 1776.5371 | E3: 33.774991 | F3: 233.5 | G3: 1522.5371 | H3: 33.774991 | I3: 0.11547005
A4: 253 | B4: 1690 | C4: 1853 | D4: 1769.6243 | E4: 47.054047 | F4: 234.5 | G4: 1514.6243 | H4: 47.054047 | I4: 0.11547005
A5: 254 | B5: 1630 | C5: 1782 | D5: 1704.3063 | E5: 43.87862 | F5: 235.5 | G5: 1448.3063 | H5: 43.87862 | I5: 0.11547005
A6: 255 | B6: 1605 | C6: 1745 | D6: 1673.5367 | E6: 40.414519 | F6: 236.5 | G6: 1416.5367 | H6: 40.414519 | I6: 0.11547005
A7: 256 | B7: 1574 | C7: 1710 | D7: 1640.5914 | E7: 39.259818 | F7: 237.5 | G7: 1382.5914 | H7: 39.259818 | I7: 0.11547005
A8: 257 | B8: 1546 | C8: 1679 | D8: 1611.1282 | E8: 38.393793 | F8: 238.5 | G8: 1352.1282 | H8: 38.393793 | I8: 0.11547005
A9: 258 | B9: 1525 | C9: 1629 | D9: 1576.1424 | E9: 30.022214 | F9: 239.5 | G9: 1316.1424 | H9: 30.022214 | I9: 0.11547005
A10: 259 | B10: 1505 | C10: 1603 | D10: 1553.2273 | E10: 28.290163 | F10: 240.5 | G10: 1292.2273 | H10: 28.290163 | I10: 0.11547005
A11: 260 | B11: 1467 | C11: 1572 | D11: 1518.5928 | E11: 30.310889 | F11: 241.5 | G11: 1256.5928 | H11: 30.310889 | I11: 0.11547005
A12: 261 | B12: 1452 | C12: 1534 | D12: 1492.4369 | E12: 23.671361 | F12: 242.5 | G12: 1229.4369 | H12: 23.671361 | I12: 0.11547005
A13: 262 | B13: 1442 | C13: 1520 | D13: 1480.4864 | E13: 22.51666 | F13: 243.5 | G13: 1216.4864 | H13: 22.51666 | I13: 0.11547005
... A62: 330 | B62: 906 | C62: 915 | D62: 910.48888 | E62: 2.5980762 | F62: 311.5 | G62: 578.48888 | H62: 2.5980762 | I62: 0.11547005
A63: 335 | B63: 886 | D63: 886 | E63: 0.11547005 | F63: 316.5 | G63: 549 | H63: 0.11547005 | I63: 0.11547005
A64: 340 | B64: 871 | D64: 871 | E64: 0.11547005 | F64: 321.5 | G64: 529 | H64: 0.11547005 | I64: 0.11547005
A65: 345 | B65: 870 | D65: 870 | E65: 0.11547005 | F65: 326.5 | G65: 523 | H65: 0.11547005 | I65: 0.11547005
A66: 350 | B66: 864 | D66: 864 | E66: 0.11547005 | F66: 331.5 | G66: 512 | H66: 0.11547005 | I66: 0.11547005
A67: 355 | B67: 856 | D67: 856 | E67: 0.11547005 | F67: 336.5 | G67: 499 | H67: 0.11547005 | I67: 0.11547005
A68: 360 | B68: 851 | D68: 851 | E68: 0.11547005 | F68: 341.5 | G68: 489 | H68: 0.11547005 | I68: 0.11547005
A69: 365 | B69: 846 | D69: 846 | E69: 0.11547005 | F69: 346.5 | G69: 479 | H69: 0.11547005 | I69: 0.11547005
A70: 370 | B70: 840 | D70: 840 | E70: 0.11547005 | F70: 351.5 | G70: 468 | H70: 0.11547005 | I70: 0.11547005
A71: 375 | B71: 835 | D71: 835 | E71: 0.11547005 | F71: 356.5 | G71: 458 | H71: 0.11547005 | I71: 0.11547005
A72: 380 | B72: 833 | D72: 833 | E72: 0.11547005 | F72: 361.5 | G72: 451 | H72: 0.11547005 | I72: 0.11547005
A73: 385 | B73: 832 | D73: 832 | E73: 0.11547005 | F73: 366.5 | G73: 445 | H73: 0.11547005 | I73: 0.11547005
A74: 390 | B74: 828 | D74: 828 | E74: 0.11547005 | F74: 371.5 | G74: 436 | H74: 0.11547005 | I74: 0.11547005
... A117: 1650 | B117: 1882 | D117: 1882 | E117: 0.11547005 | F117: 1631.5 | G117: 223 | H117: 0.11547005 | I117: 0.11547005

Sheet Sheet2
A1: p | B1: q | C1: sigma_p | D1: sigma_q
A2: 232.5 | B2: 1568.3956 | C2: 0.11547005 | D2: 11.25833
A3: 233.5 | B3: 1522.5371 | C3: 0.11547005 | D3: 33.774991
A4: 234.5 | B4: 1514.6243 | C4: 0.11547005 | D4: 47.054047
A5: 235.5 | B5: 1448.3063 | C5: 0.11547005 | D5: 43.87862
A6: 236.5 | B6: 1416.5367 | C6: 0.11547005 | D6: 40.414519
A7: 237.5 | B7: 1382.5914 | C7: 0.11547005 | D7: 39.259818
A8: 238.5 | B8: 1352.1282 | C8: 0.11547005 | D8: 38.393793
A9: 239.5 | B9: 1316.1424 | C9: 0.11547005 | D9: 30.022214
A10: 240.5 | B10: 1292.2273 | C10: 0.11547005 | D10: 28.290163
A11: 241.5 | B11: 1256.5928 | C11: 0.11547005 | D11: 30.310889
A12: 242.5 | B12: 1229.4369 | C12: 0.11547005 | D12: 23.671361
A13: 243.5 | B13: 1216.4864 | C13: 0.11547005 | D13: 22.51666
... A117: 1631.5 | B117: 230 | C117: 0.11547005 | D117: 0.11547005
